2019-08-23 09:22:36,150 -  nornir.core -     INFO -        run() - Running task 'napalm_get' with args {'getters': ['config']} on 2 hosts
2019-08-23 09:22:39,034 - nornir.core.task -    ERROR -      start() - Host 'CSR-1': task 'napalm_get' failed with traceback:
Traceback (most recent call last):
  File "/Library/Frameworks/Python.framework/Versions/3.7/lib/python3.7/site-packages/netmiko/base_connection.py", line 864, in establish_connection
    self.remote_conn_pre.connect(**ssh_connect_params)
  File "/Library/Frameworks/Python.framework/Versions/3.7/lib/python3.7/site-packages/paramiko/client.py", line 446, in connect
    passphrase,
  File "/Library/Frameworks/Python.framework/Versions/3.7/lib/python3.7/site-packages/paramiko/client.py", line 764, in _auth
    raise saved_exception
  File "/Library/Frameworks/Python.framework/Versions/3.7/lib/python3.7/site-packages/paramiko/client.py", line 751, in _auth
    self._transport.auth_password(username, password)
  File "/Library/Frameworks/Python.framework/Versions/3.7/lib/python3.7/site-packages/paramiko/transport.py", line 1509, in auth_password
    return self.auth_handler.wait_for_response(my_event)
  File "/Library/Frameworks/Python.framework/Versions/3.7/lib/python3.7/site-packages/paramiko/auth_handler.py", line 250, in wait_for_response
    raise e
paramiko.ssh_exception.AuthenticationException: Authentication failed.

During handling of the above exception, another exception occurred:

Traceback (most recent call last):
  File "/Library/Frameworks/Python.framework/Versions/3.7/lib/python3.7/site-packages/nornir/core/task.py", line 67, in start
    r = self.task(self, **self.params)
  File "/Library/Frameworks/Python.framework/Versions/3.7/lib/python3.7/site-packages/nornir/plugins/tasks/networking/napalm_get.py", line 49, in napalm_get
    device = task.host.get_connection("napalm", task.nornir.config)
  File "/Library/Frameworks/Python.framework/Versions/3.7/lib/python3.7/site-packages/nornir/core/inventory.py", line 302, in get_connection
    extras=conn.extras,
  File "/Library/Frameworks/Python.framework/Versions/3.7/lib/python3.7/site-packages/nornir/core/inventory.py", line 352, in open_connection
    configuration=configuration,
  File "/Library/Frameworks/Python.framework/Versions/3.7/lib/python3.7/site-packages/nornir/plugins/connections/napalm.py", line 51, in open
    connection.open()
  File "/Library/Frameworks/Python.framework/Versions/3.7/lib/python3.7/site-packages/napalm/ios/ios.py", line 151, in open
    device_type, netmiko_optional_args=self.netmiko_optional_args
  File "/Library/Frameworks/Python.framework/Versions/3.7/lib/python3.7/site-packages/napalm/base/base.py", line 87, in _netmiko_open
    **netmiko_optional_args
  File "/Library/Frameworks/Python.framework/Versions/3.7/lib/python3.7/site-packages/netmiko/ssh_dispatcher.py", line 242, in ConnectHandler
    return ConnectionClass(*args, **kwargs)
  File "/Library/Frameworks/Python.framework/Versions/3.7/lib/python3.7/site-packages/netmiko/base_connection.py", line 312, in __init__
    self._open()
  File "/Library/Frameworks/Python.framework/Versions/3.7/lib/python3.7/site-packages/netmiko/base_connection.py", line 317, in _open
    self.establish_connection()
  File "/Library/Frameworks/Python.framework/Versions/3.7/lib/python3.7/site-packages/netmiko/base_connection.py", line 877, in establish_connection
    raise NetMikoAuthenticationException(msg)
netmiko.ssh_exception.NetMikoAuthenticationException: Authentication failure: unable to connect cisco_ios CSR-1.threefddi.local:22
Authentication failed.

2019-08-23 09:22:41,533 - nornir.core.task -    ERROR -      start() - Host 'CSR-2': task 'napalm_get' failed with traceback:
Traceback (most recent call last):
  File "/Library/Frameworks/Python.framework/Versions/3.7/lib/python3.7/site-packages/netmiko/base_connection.py", line 864, in establish_connection
    self.remote_conn_pre.connect(**ssh_connect_params)
  File "/Library/Frameworks/Python.framework/Versions/3.7/lib/python3.7/site-packages/paramiko/client.py", line 446, in connect
    passphrase,
  File "/Library/Frameworks/Python.framework/Versions/3.7/lib/python3.7/site-packages/paramiko/client.py", line 764, in _auth
    raise saved_exception
  File "/Library/Frameworks/Python.framework/Versions/3.7/lib/python3.7/site-packages/paramiko/client.py", line 751, in _auth
    self._transport.auth_password(username, password)
  File "/Library/Frameworks/Python.framework/Versions/3.7/lib/python3.7/site-packages/paramiko/transport.py", line 1509, in auth_password
    return self.auth_handler.wait_for_response(my_event)
  File "/Library/Frameworks/Python.framework/Versions/3.7/lib/python3.7/site-packages/paramiko/auth_handler.py", line 250, in wait_for_response
    raise e
paramiko.ssh_exception.AuthenticationException: Authentication failed.

During handling of the above exception, another exception occurred:

Traceback (most recent call last):
  File "/Library/Frameworks/Python.framework/Versions/3.7/lib/python3.7/site-packages/nornir/core/task.py", line 67, in start
    r = self.task(self, **self.params)
  File "/Library/Frameworks/Python.framework/Versions/3.7/lib/python3.7/site-packages/nornir/plugins/tasks/networking/napalm_get.py", line 49, in napalm_get
    device = task.host.get_connection("napalm", task.nornir.config)
  File "/Library/Frameworks/Python.framework/Versions/3.7/lib/python3.7/site-packages/nornir/core/inventory.py", line 302, in get_connection
    extras=conn.extras,
  File "/Library/Frameworks/Python.framework/Versions/3.7/lib/python3.7/site-packages/nornir/core/inventory.py", line 352, in open_connection
    configuration=configuration,
  File "/Library/Frameworks/Python.framework/Versions/3.7/lib/python3.7/site-packages/nornir/plugins/connections/napalm.py", line 51, in open
    connection.open()
  File "/Library/Frameworks/Python.framework/Versions/3.7/lib/python3.7/site-packages/napalm/ios/ios.py", line 151, in open
    device_type, netmiko_optional_args=self.netmiko_optional_args
  File "/Library/Frameworks/Python.framework/Versions/3.7/lib/python3.7/site-packages/napalm/base/base.py", line 87, in _netmiko_open
    **netmiko_optional_args
  File "/Library/Frameworks/Python.framework/Versions/3.7/lib/python3.7/site-packages/netmiko/ssh_dispatcher.py", line 242, in ConnectHandler
    return ConnectionClass(*args, **kwargs)
  File "/Library/Frameworks/Python.framework/Versions/3.7/lib/python3.7/site-packages/netmiko/base_connection.py", line 312, in __init__
    self._open()
  File "/Library/Frameworks/Python.framework/Versions/3.7/lib/python3.7/site-packages/netmiko/base_connection.py", line 317, in _open
    self.establish_connection()
  File "/Library/Frameworks/Python.framework/Versions/3.7/lib/python3.7/site-packages/netmiko/base_connection.py", line 877, in establish_connection
    raise NetMikoAuthenticationException(msg)
netmiko.ssh_exception.NetMikoAuthenticationException: Authentication failure: unable to connect cisco_ios CSR-2.threefddi.local:22
Authentication failed.

2019-08-23 09:24:48,286 -  nornir.core -     INFO -        run() - Running task 'napalm_get' with args {'getters': ['lldp_neighbors', 'interfaces_ip', 'facts', 'network_instances', 'config']} on 2 hosts
2019-08-23 09:24:50,823 - nornir.core.task -    ERROR -      start() - Host 'CSR-1': task 'napalm_get' failed with traceback:
Traceback (most recent call last):
  File "/Library/Frameworks/Python.framework/Versions/3.7/lib/python3.7/site-packages/netmiko/base_connection.py", line 864, in establish_connection
    self.remote_conn_pre.connect(**ssh_connect_params)
  File "/Library/Frameworks/Python.framework/Versions/3.7/lib/python3.7/site-packages/paramiko/client.py", line 446, in connect
    passphrase,
  File "/Library/Frameworks/Python.framework/Versions/3.7/lib/python3.7/site-packages/paramiko/client.py", line 764, in _auth
    raise saved_exception
  File "/Library/Frameworks/Python.framework/Versions/3.7/lib/python3.7/site-packages/paramiko/client.py", line 751, in _auth
    self._transport.auth_password(username, password)
  File "/Library/Frameworks/Python.framework/Versions/3.7/lib/python3.7/site-packages/paramiko/transport.py", line 1509, in auth_password
    return self.auth_handler.wait_for_response(my_event)
  File "/Library/Frameworks/Python.framework/Versions/3.7/lib/python3.7/site-packages/paramiko/auth_handler.py", line 250, in wait_for_response
    raise e
paramiko.ssh_exception.AuthenticationException: Authentication failed.

During handling of the above exception, another exception occurred:

Traceback (most recent call last):
  File "/Library/Frameworks/Python.framework/Versions/3.7/lib/python3.7/site-packages/nornir/core/task.py", line 67, in start
    r = self.task(self, **self.params)
  File "/Library/Frameworks/Python.framework/Versions/3.7/lib/python3.7/site-packages/nornir/plugins/tasks/networking/napalm_get.py", line 49, in napalm_get
    device = task.host.get_connection("napalm", task.nornir.config)
  File "/Library/Frameworks/Python.framework/Versions/3.7/lib/python3.7/site-packages/nornir/core/inventory.py", line 302, in get_connection
    extras=conn.extras,
  File "/Library/Frameworks/Python.framework/Versions/3.7/lib/python3.7/site-packages/nornir/core/inventory.py", line 352, in open_connection
    configuration=configuration,
  File "/Library/Frameworks/Python.framework/Versions/3.7/lib/python3.7/site-packages/nornir/plugins/connections/napalm.py", line 51, in open
    connection.open()
  File "/Library/Frameworks/Python.framework/Versions/3.7/lib/python3.7/site-packages/napalm/ios/ios.py", line 151, in open
    device_type, netmiko_optional_args=self.netmiko_optional_args
  File "/Library/Frameworks/Python.framework/Versions/3.7/lib/python3.7/site-packages/napalm/base/base.py", line 87, in _netmiko_open
    **netmiko_optional_args
  File "/Library/Frameworks/Python.framework/Versions/3.7/lib/python3.7/site-packages/netmiko/ssh_dispatcher.py", line 242, in ConnectHandler
    return ConnectionClass(*args, **kwargs)
  File "/Library/Frameworks/Python.framework/Versions/3.7/lib/python3.7/site-packages/netmiko/base_connection.py", line 312, in __init__
    self._open()
  File "/Library/Frameworks/Python.framework/Versions/3.7/lib/python3.7/site-packages/netmiko/base_connection.py", line 317, in _open
    self.establish_connection()
  File "/Library/Frameworks/Python.framework/Versions/3.7/lib/python3.7/site-packages/netmiko/base_connection.py", line 877, in establish_connection
    raise NetMikoAuthenticationException(msg)
netmiko.ssh_exception.NetMikoAuthenticationException: Authentication failure: unable to connect cisco_ios CSR-1.threefddi.local:22
Authentication failed.

2019-08-23 09:24:53,321 - nornir.core.task -    ERROR -      start() - Host 'CSR-2': task 'napalm_get' failed with traceback:
Traceback (most recent call last):
  File "/Library/Frameworks/Python.framework/Versions/3.7/lib/python3.7/site-packages/netmiko/base_connection.py", line 864, in establish_connection
    self.remote_conn_pre.connect(**ssh_connect_params)
  File "/Library/Frameworks/Python.framework/Versions/3.7/lib/python3.7/site-packages/paramiko/client.py", line 446, in connect
    passphrase,
  File "/Library/Frameworks/Python.framework/Versions/3.7/lib/python3.7/site-packages/paramiko/client.py", line 764, in _auth
    raise saved_exception
  File "/Library/Frameworks/Python.framework/Versions/3.7/lib/python3.7/site-packages/paramiko/client.py", line 751, in _auth
    self._transport.auth_password(username, password)
  File "/Library/Frameworks/Python.framework/Versions/3.7/lib/python3.7/site-packages/paramiko/transport.py", line 1509, in auth_password
    return self.auth_handler.wait_for_response(my_event)
  File "/Library/Frameworks/Python.framework/Versions/3.7/lib/python3.7/site-packages/paramiko/auth_handler.py", line 250, in wait_for_response
    raise e
paramiko.ssh_exception.AuthenticationException: Authentication failed.

During handling of the above exception, another exception occurred:

Traceback (most recent call last):
  File "/Library/Frameworks/Python.framework/Versions/3.7/lib/python3.7/site-packages/nornir/core/task.py", line 67, in start
    r = self.task(self, **self.params)
  File "/Library/Frameworks/Python.framework/Versions/3.7/lib/python3.7/site-packages/nornir/plugins/tasks/networking/napalm_get.py", line 49, in napalm_get
    device = task.host.get_connection("napalm", task.nornir.config)
  File "/Library/Frameworks/Python.framework/Versions/3.7/lib/python3.7/site-packages/nornir/core/inventory.py", line 302, in get_connection
    extras=conn.extras,
  File "/Library/Frameworks/Python.framework/Versions/3.7/lib/python3.7/site-packages/nornir/core/inventory.py", line 352, in open_connection
    configuration=configuration,
  File "/Library/Frameworks/Python.framework/Versions/3.7/lib/python3.7/site-packages/nornir/plugins/connections/napalm.py", line 51, in open
    connection.open()
  File "/Library/Frameworks/Python.framework/Versions/3.7/lib/python3.7/site-packages/napalm/ios/ios.py", line 151, in open
    device_type, netmiko_optional_args=self.netmiko_optional_args
  File "/Library/Frameworks/Python.framework/Versions/3.7/lib/python3.7/site-packages/napalm/base/base.py", line 87, in _netmiko_open
    **netmiko_optional_args
  File "/Library/Frameworks/Python.framework/Versions/3.7/lib/python3.7/site-packages/netmiko/ssh_dispatcher.py", line 242, in ConnectHandler
    return ConnectionClass(*args, **kwargs)
  File "/Library/Frameworks/Python.framework/Versions/3.7/lib/python3.7/site-packages/netmiko/base_connection.py", line 312, in __init__
    self._open()
  File "/Library/Frameworks/Python.framework/Versions/3.7/lib/python3.7/site-packages/netmiko/base_connection.py", line 317, in _open
    self.establish_connection()
  File "/Library/Frameworks/Python.framework/Versions/3.7/lib/python3.7/site-packages/netmiko/base_connection.py", line 877, in establish_connection
    raise NetMikoAuthenticationException(msg)
netmiko.ssh_exception.NetMikoAuthenticationException: Authentication failure: unable to connect cisco_ios CSR-2.threefddi.local:22
Authentication failed.

2019-08-23 09:25:56,936 -  nornir.core -  WARNING -        run() - Task 'netmiko_send_command' has not been run – 0 hosts selected
2019-08-23 09:25:57,051 -  nornir.core -  WARNING -        run() - Task 'netmiko_send_command' has not been run – 0 hosts selected
2019-08-23 09:25:57,157 -  nornir.core -  WARNING -        run() - Task 'netmiko_send_command' has not been run – 0 hosts selected
2019-08-23 09:25:57,265 -  nornir.core -  WARNING -        run() - Task 'netmiko_send_command' has not been run – 0 hosts selected
2019-08-23 09:25:57,374 -  nornir.core -  WARNING -        run() - Task 'netmiko_send_command' has not been run – 0 hosts selected
2019-08-23 09:25:57,479 -  nornir.core -  WARNING -        run() - Task 'netmiko_send_command' has not been run – 0 hosts selected
2019-08-23 09:26:22,039 -  nornir.core -  WARNING -        run() - Task 'netmiko_send_command' has not been run – 0 hosts selected
2019-08-23 09:26:22,150 -  nornir.core -  WARNING -        run() - Task 'netmiko_send_command' has not been run – 0 hosts selected
2019-08-23 09:26:22,257 -  nornir.core -  WARNING -        run() - Task 'netmiko_send_command' has not been run – 0 hosts selected
2019-08-23 09:26:22,365 -  nornir.core -  WARNING -        run() - Task 'netmiko_send_command' has not been run – 0 hosts selected
2019-08-23 09:26:22,472 -  nornir.core -  WARNING -        run() - Task 'netmiko_send_command' has not been run – 0 hosts selected
2019-08-23 09:26:22,581 -  nornir.core -  WARNING -        run() - Task 'netmiko_send_command' has not been run – 0 hosts selected
2019-08-23 09:29:12,973 -  nornir.core -  WARNING -        run() - Task 'napalm_get' has not been run – 0 hosts selected
2019-08-23 09:29:30,224 -  nornir.core -  WARNING -        run() - Task 'netmiko_send_command' has not been run – 0 hosts selected
2019-08-23 09:29:30,334 -  nornir.core -  WARNING -        run() - Task 'netmiko_send_command' has not been run – 0 hosts selected
2019-08-23 09:29:30,440 -  nornir.core -  WARNING -        run() - Task 'netmiko_send_command' has not been run – 0 hosts selected
2019-08-23 09:29:30,547 -  nornir.core -  WARNING -        run() - Task 'netmiko_send_command' has not been run – 0 hosts selected
2019-08-23 09:29:30,651 -  nornir.core -  WARNING -        run() - Task 'netmiko_send_command' has not been run – 0 hosts selected
2019-08-23 09:29:30,758 -  nornir.core -  WARNING -        run() - Task 'netmiko_send_command' has not been run – 0 hosts selected
2019-08-23 09:34:07,466 -  nornir.core -  WARNING -        run() - Task 'netmiko_send_command' has not been run – 0 hosts selected
2019-08-23 09:34:07,576 -  nornir.core -  WARNING -        run() - Task 'netmiko_send_command' has not been run – 0 hosts selected
2019-08-23 09:34:07,684 -  nornir.core -  WARNING -        run() - Task 'netmiko_send_command' has not been run – 0 hosts selected
2019-08-23 09:34:07,793 -  nornir.core -  WARNING -        run() - Task 'netmiko_send_command' has not been run – 0 hosts selected
2019-08-23 09:34:07,900 -  nornir.core -  WARNING -        run() - Task 'netmiko_send_command' has not been run – 0 hosts selected
2019-08-23 09:34:08,007 -  nornir.core -  WARNING -        run() - Task 'netmiko_send_command' has not been run – 0 hosts selected
2019-08-23 09:34:21,652 -  nornir.core -  WARNING -        run() - Task 'netmiko_send_command' has not been run – 0 hosts selected
2019-08-23 09:34:21,762 -  nornir.core -  WARNING -        run() - Task 'netmiko_send_command' has not been run – 0 hosts selected
2019-08-23 09:34:21,868 -  nornir.core -  WARNING -        run() - Task 'netmiko_send_command' has not been run – 0 hosts selected
2019-08-23 09:34:21,977 -  nornir.core -  WARNING -        run() - Task 'netmiko_send_command' has not been run – 0 hosts selected
2019-08-23 09:34:22,083 -  nornir.core -  WARNING -        run() - Task 'netmiko_send_command' has not been run – 0 hosts selected
2019-08-23 09:34:22,188 -  nornir.core -  WARNING -        run() - Task 'netmiko_send_command' has not been run – 0 hosts selected
2019-08-23 09:34:36,777 -  nornir.core -     INFO -        run() - Running task 'netmiko_send_command' with args {'command_string': 'show version'} on 2 hosts
2019-08-23 09:34:39,366 - nornir.core.task -    ERROR -      start() - Host 'CSR-1': task 'netmiko_send_command' failed with traceback:
Traceback (most recent call last):
  File "/Library/Frameworks/Python.framework/Versions/3.7/lib/python3.7/site-packages/netmiko/base_connection.py", line 864, in establish_connection
    self.remote_conn_pre.connect(**ssh_connect_params)
  File "/Library/Frameworks/Python.framework/Versions/3.7/lib/python3.7/site-packages/paramiko/client.py", line 446, in connect
    passphrase,
  File "/Library/Frameworks/Python.framework/Versions/3.7/lib/python3.7/site-packages/paramiko/client.py", line 764, in _auth
    raise saved_exception
  File "/Library/Frameworks/Python.framework/Versions/3.7/lib/python3.7/site-packages/paramiko/client.py", line 751, in _auth
    self._transport.auth_password(username, password)
  File "/Library/Frameworks/Python.framework/Versions/3.7/lib/python3.7/site-packages/paramiko/transport.py", line 1509, in auth_password
    return self.auth_handler.wait_for_response(my_event)
  File "/Library/Frameworks/Python.framework/Versions/3.7/lib/python3.7/site-packages/paramiko/auth_handler.py", line 250, in wait_for_response
    raise e
paramiko.ssh_exception.AuthenticationException: Authentication failed.

During handling of the above exception, another exception occurred:

Traceback (most recent call last):
  File "/Library/Frameworks/Python.framework/Versions/3.7/lib/python3.7/site-packages/nornir/core/task.py", line 67, in start
    r = self.task(self, **self.params)
  File "/Library/Frameworks/Python.framework/Versions/3.7/lib/python3.7/site-packages/nornir/plugins/tasks/networking/netmiko_send_command.py", line 26, in netmiko_send_command
    net_connect = task.host.get_connection("netmiko", task.nornir.config)
  File "/Library/Frameworks/Python.framework/Versions/3.7/lib/python3.7/site-packages/nornir/core/inventory.py", line 302, in get_connection
    extras=conn.extras,
  File "/Library/Frameworks/Python.framework/Versions/3.7/lib/python3.7/site-packages/nornir/core/inventory.py", line 352, in open_connection
    configuration=configuration,
  File "/Library/Frameworks/Python.framework/Versions/3.7/lib/python3.7/site-packages/nornir/plugins/connections/netmiko.py", line 58, in open
    self.connection = ConnectHandler(**parameters)
  File "/Library/Frameworks/Python.framework/Versions/3.7/lib/python3.7/site-packages/netmiko/ssh_dispatcher.py", line 242, in ConnectHandler
    return ConnectionClass(*args, **kwargs)
  File "/Library/Frameworks/Python.framework/Versions/3.7/lib/python3.7/site-packages/netmiko/base_connection.py", line 312, in __init__
    self._open()
  File "/Library/Frameworks/Python.framework/Versions/3.7/lib/python3.7/site-packages/netmiko/base_connection.py", line 317, in _open
    self.establish_connection()
  File "/Library/Frameworks/Python.framework/Versions/3.7/lib/python3.7/site-packages/netmiko/base_connection.py", line 877, in establish_connection
    raise NetMikoAuthenticationException(msg)
netmiko.ssh_exception.NetMikoAuthenticationException: Authentication failure: unable to connect cisco_ios CSR-1.threefddi.local:22
Authentication failed.

2019-08-23 09:34:39,366 - nornir.core.task -    ERROR -      start() - Host 'CSR-2': task 'netmiko_send_command' failed with traceback:
Traceback (most recent call last):
  File "/Library/Frameworks/Python.framework/Versions/3.7/lib/python3.7/site-packages/netmiko/base_connection.py", line 864, in establish_connection
    self.remote_conn_pre.connect(**ssh_connect_params)
  File "/Library/Frameworks/Python.framework/Versions/3.7/lib/python3.7/site-packages/paramiko/client.py", line 446, in connect
    passphrase,
  File "/Library/Frameworks/Python.framework/Versions/3.7/lib/python3.7/site-packages/paramiko/client.py", line 764, in _auth
    raise saved_exception
  File "/Library/Frameworks/Python.framework/Versions/3.7/lib/python3.7/site-packages/paramiko/client.py", line 751, in _auth
    self._transport.auth_password(username, password)
  File "/Library/Frameworks/Python.framework/Versions/3.7/lib/python3.7/site-packages/paramiko/transport.py", line 1509, in auth_password
    return self.auth_handler.wait_for_response(my_event)
  File "/Library/Frameworks/Python.framework/Versions/3.7/lib/python3.7/site-packages/paramiko/auth_handler.py", line 250, in wait_for_response
    raise e
paramiko.ssh_exception.AuthenticationException: Authentication failed.

During handling of the above exception, another exception occurred:

Traceback (most recent call last):
  File "/Library/Frameworks/Python.framework/Versions/3.7/lib/python3.7/site-packages/nornir/core/task.py", line 67, in start
    r = self.task(self, **self.params)
  File "/Library/Frameworks/Python.framework/Versions/3.7/lib/python3.7/site-packages/nornir/plugins/tasks/networking/netmiko_send_command.py", line 26, in netmiko_send_command
    net_connect = task.host.get_connection("netmiko", task.nornir.config)
  File "/Library/Frameworks/Python.framework/Versions/3.7/lib/python3.7/site-packages/nornir/core/inventory.py", line 302, in get_connection
    extras=conn.extras,
  File "/Library/Frameworks/Python.framework/Versions/3.7/lib/python3.7/site-packages/nornir/core/inventory.py", line 352, in open_connection
    configuration=configuration,
  File "/Library/Frameworks/Python.framework/Versions/3.7/lib/python3.7/site-packages/nornir/plugins/connections/netmiko.py", line 58, in open
    self.connection = ConnectHandler(**parameters)
  File "/Library/Frameworks/Python.framework/Versions/3.7/lib/python3.7/site-packages/netmiko/ssh_dispatcher.py", line 242, in ConnectHandler
    return ConnectionClass(*args, **kwargs)
  File "/Library/Frameworks/Python.framework/Versions/3.7/lib/python3.7/site-packages/netmiko/base_connection.py", line 312, in __init__
    self._open()
  File "/Library/Frameworks/Python.framework/Versions/3.7/lib/python3.7/site-packages/netmiko/base_connection.py", line 317, in _open
    self.establish_connection()
  File "/Library/Frameworks/Python.framework/Versions/3.7/lib/python3.7/site-packages/netmiko/base_connection.py", line 877, in establish_connection
    raise NetMikoAuthenticationException(msg)
netmiko.ssh_exception.NetMikoAuthenticationException: Authentication failure: unable to connect cisco_ios CSR-2.threefddi.local:22
Authentication failed.

2019-08-23 09:34:39,402 -  nornir.core -     INFO -        run() - Running task 'netmiko_send_command' with args {'command_string': 'show run'} on 2 hosts
2019-08-23 09:34:39,508 -  nornir.core -     INFO -        run() - Running task 'netmiko_send_command' with args {'command_string': 'show ip interface brief'} on 2 hosts
2019-08-23 09:34:39,616 -  nornir.core -     INFO -        run() - Running task 'netmiko_send_command' with args {'command_string': 'sh ip route'} on 2 hosts
2019-08-23 09:34:39,724 -  nornir.core -     INFO -        run() - Running task 'netmiko_send_command' with args {'command_string': 'show cdp neighbors'} on 2 hosts
2019-08-23 09:34:39,831 -  nornir.core -     INFO -        run() - Running task 'netmiko_send_command' with args {'command_string': 'show cdp neighbors detail'} on 2 hosts
2019-08-23 09:35:15,628 -  nornir.core -     INFO -        run() - Running task 'netmiko_send_command' with args {'command_string': 'show version'} on 2 hosts
2019-08-23 09:35:20,943 -  nornir.core -     INFO -        run() - Running task 'netmiko_send_command' with args {'command_string': 'show run'} on 2 hosts
2019-08-23 09:35:21,569 -  nornir.core -     INFO -        run() - Running task 'netmiko_send_command' with args {'command_string': 'show ip interface brief'} on 2 hosts
2019-08-23 09:35:22,197 -  nornir.core -     INFO -        run() - Running task 'netmiko_send_command' with args {'command_string': 'sh ip route'} on 2 hosts
2019-08-23 09:35:22,822 -  nornir.core -     INFO -        run() - Running task 'netmiko_send_command' with args {'command_string': 'show cdp neighbors'} on 2 hosts
2019-08-23 09:35:23,449 -  nornir.core -     INFO -        run() - Running task 'netmiko_send_command' with args {'command_string': 'show cdp neighbors detail'} on 2 hosts
2019-08-23 09:35:51,245 -  nornir.core -     INFO -        run() - Running task 'napalm_get' with args {'getters': ['lldp_neighbors', 'interfaces_ip', 'facts', 'network_instances', 'config']} on 2 hosts
2019-08-23 09:36:27,036 -  nornir.core -     INFO -        run() - Running task 'napalm_get' with args {'getters': ['config']} on 2 hosts
2019-08-23 11:04:05,305 -  nornir.core -     INFO -        run() - Running task 'napalm_get' with args {'getters': ['config']} on 2 hosts
