2019-11-05 18:09:16,360 -  nornir.core -     INFO -        run() - Running task 'netmiko_send_command' with args {'command_string': 'show interface switchport', 'use_textfsm': True} on 2 hosts
2019-11-05 18:09:49,559 -  nornir.core -     INFO -        run() - Running task 'netmiko_send_command' with args {'command_string': 'show interface switchport', 'use_textfsm': True} on 2 hosts
2019-11-05 18:12:08,227 -  nornir.core -     INFO -        run() - Running task 'netmiko_send_command' with args {'command_string': 'show interface switchport', 'use_textfsm': True} on 2 hosts
2019-11-05 18:12:37,280 -  nornir.core -     INFO -        run() - Running task 'netmiko_send_command' with args {'command_string': 'show interface switchport', 'use_textfsm': True} on 2 hosts
2019-11-05 18:13:13,948 -  nornir.core -     INFO -        run() - Running task 'netmiko_send_command' with args {'command_string': 'show interface switchport', 'use_textfsm': True} on 2 hosts
2019-11-05 18:15:20,447 -  nornir.core -     INFO -        run() - Running task 'netmiko_send_command' with args {'command_string': 'show interface switchport', 'use_textfsm': True} on 2 hosts
2019-11-05 18:16:28,836 -  nornir.core -     INFO -        run() - Running task 'netmiko_send_command' with args {'command_string': 'show interface switchport', 'use_textfsm': True} on 2 hosts
2019-11-05 18:17:51,217 -  nornir.core -     INFO -        run() - Running task 'netmiko_send_command' with args {'command_string': 'show interface switchport', 'use_textfsm': True} on 2 hosts
2019-11-05 18:24:10,982 -  nornir.core -     INFO -        run() - Running task 'netmiko_send_command' with args {'command_string': 'show interface switchport', 'use_textfsm': True} on 2 hosts
2019-11-05 18:25:51,034 -  nornir.core -     INFO -        run() - Running task 'netmiko_send_command' with args {'command_string': 'show interface switchport', 'use_textfsm': True} on 2 hosts
2019-11-05 18:27:54,237 -  nornir.core -     INFO -        run() - Running task 'netmiko_send_command' with args {'command_string': 'show interface switchport', 'use_textfsm': True} on 2 hosts
2019-11-05 18:28:16,068 -  nornir.core -     INFO -        run() - Running task 'netmiko_send_command' with args {'command_string': 'show interface switchport', 'use_textfsm': True} on 2 hosts
2019-11-05 18:30:59,673 -  nornir.core -     INFO -        run() - Running task 'netmiko_send_command' with args {'command_string': 'show interface switchport', 'use_textfsm': True} on 2 hosts
2019-11-05 18:36:27,128 -  nornir.core -     INFO -        run() - Running task 'netmiko_send_command' with args {'command_string': 'show interface switchport', 'use_textfsm': True} on 2 hosts
2019-11-05 18:36:49,038 -  nornir.core -     INFO -        run() - Running task 'netmiko_send_command' with args {'command_string': 'show interface switchport', 'use_textfsm': True} on 2 hosts
2019-11-05 18:36:55,649 -  nornir.core -     INFO -        run() - Running task 'push_configs' with args {} on 2 hosts
2019-11-05 18:37:24,466 - nornir.core.task -    ERROR -      start() - Host 'NXOS-2': task 'napalm_configure' failed with traceback:
Traceback (most recent call last):
  File "/Library/Frameworks/Python.framework/Versions/3.7/lib/python3.7/site-packages/napalm/nxos/nxos.py", line 145, in _commit_merge
    output = self._send_config(self.merge_candidate)
  File "/Library/Frameworks/Python.framework/Versions/3.7/lib/python3.7/site-packages/napalm/nxos/nxos.py", line 652, in _send_config
    return self.device.config_list(commands)
  File "/Library/Frameworks/Python.framework/Versions/3.7/lib/python3.7/site-packages/nxapi_plumbing/device.py", line 126, in config_list
    return self.api._nxapi_command_conf(commands)
  File "/Library/Frameworks/Python.framework/Versions/3.7/lib/python3.7/site-packages/nxapi_plumbing/api_client.py", line 112, in _nxapi_command_conf
    return self._nxapi_command(commands=commands, method=method)
  File "/Library/Frameworks/Python.framework/Versions/3.7/lib/python3.7/site-packages/nxapi_plumbing/api_client.py", line 105, in _nxapi_command
    response = self._send_request(commands, method=method)
  File "/Library/Frameworks/Python.framework/Versions/3.7/lib/python3.7/site-packages/nxapi_plumbing/api_client.py", line 82, in _send_request
    raise NXAPIPostError(msg)
nxapi_plumbing.errors.NXAPIPostError: Invalid status code returned on NX-API POST
commands: ['configs/NXOS-2_ints.txt']
status_code: 500

During handling of the above exception, another exception occurred:

Traceback (most recent call last):
  File "/Library/Frameworks/Python.framework/Versions/3.7/lib/python3.7/site-packages/nornir/core/task.py", line 85, in start
    r = self.task(self, **self.params)
  File "/Library/Frameworks/Python.framework/Versions/3.7/lib/python3.7/site-packages/nornir/plugins/tasks/networking/napalm_configure.py", line 37, in napalm_configure
    device.commit_config()
  File "/Library/Frameworks/Python.framework/Versions/3.7/lib/python3.7/site-packages/napalm/nxos/nxos.py", line 222, in commit_config
    self._commit_merge()
  File "/Library/Frameworks/Python.framework/Versions/3.7/lib/python3.7/site-packages/napalm/nxos/nxos.py", line 151, in _commit_merge
    raise MergeConfigException(str(e))
napalm.base.exceptions.MergeConfigException: Invalid status code returned on NX-API POST
commands: ['configs/NXOS-2_ints.txt']
status_code: 500

2019-11-05 18:37:24,467 - nornir.core.task -    ERROR -      start() - Host 'NXOS-2': task 'push_configs' failed with traceback:
Traceback (most recent call last):
  File "/Library/Frameworks/Python.framework/Versions/3.7/lib/python3.7/site-packages/nornir/core/task.py", line 85, in start
    r = self.task(self, **self.params)
  File "./vlan_mapper.py", line 169, in push_configs
    task.run(task=napalm_configure, configuration=f"configs/{task.host}_ints.txt")
  File "/Library/Frameworks/Python.framework/Versions/3.7/lib/python3.7/site-packages/nornir/core/task.py", line 147, in run
    raise NornirSubTaskError(task=task, result=r)
nornir.core.exceptions.NornirSubTaskError: Subtask: <function napalm_configure at 0x10f492048> (failed)


2019-11-05 18:37:35,623 - nornir.core.task -    ERROR -      start() - Host 'NXOS-1': task 'napalm_configure' failed with traceback:
Traceback (most recent call last):
  File "/Library/Frameworks/Python.framework/Versions/3.7/lib/python3.7/site-packages/napalm/nxos/nxos.py", line 145, in _commit_merge
    output = self._send_config(self.merge_candidate)
  File "/Library/Frameworks/Python.framework/Versions/3.7/lib/python3.7/site-packages/napalm/nxos/nxos.py", line 652, in _send_config
    return self.device.config_list(commands)
  File "/Library/Frameworks/Python.framework/Versions/3.7/lib/python3.7/site-packages/nxapi_plumbing/device.py", line 126, in config_list
    return self.api._nxapi_command_conf(commands)
  File "/Library/Frameworks/Python.framework/Versions/3.7/lib/python3.7/site-packages/nxapi_plumbing/api_client.py", line 112, in _nxapi_command_conf
    return self._nxapi_command(commands=commands, method=method)
  File "/Library/Frameworks/Python.framework/Versions/3.7/lib/python3.7/site-packages/nxapi_plumbing/api_client.py", line 105, in _nxapi_command
    response = self._send_request(commands, method=method)
  File "/Library/Frameworks/Python.framework/Versions/3.7/lib/python3.7/site-packages/nxapi_plumbing/api_client.py", line 82, in _send_request
    raise NXAPIPostError(msg)
nxapi_plumbing.errors.NXAPIPostError: Invalid status code returned on NX-API POST
commands: ['configs/NXOS-1_ints.txt']
status_code: 500

During handling of the above exception, another exception occurred:

Traceback (most recent call last):
  File "/Library/Frameworks/Python.framework/Versions/3.7/lib/python3.7/site-packages/nornir/core/task.py", line 85, in start
    r = self.task(self, **self.params)
  File "/Library/Frameworks/Python.framework/Versions/3.7/lib/python3.7/site-packages/nornir/plugins/tasks/networking/napalm_configure.py", line 37, in napalm_configure
    device.commit_config()
  File "/Library/Frameworks/Python.framework/Versions/3.7/lib/python3.7/site-packages/napalm/nxos/nxos.py", line 222, in commit_config
    self._commit_merge()
  File "/Library/Frameworks/Python.framework/Versions/3.7/lib/python3.7/site-packages/napalm/nxos/nxos.py", line 151, in _commit_merge
    raise MergeConfigException(str(e))
napalm.base.exceptions.MergeConfigException: Invalid status code returned on NX-API POST
commands: ['configs/NXOS-1_ints.txt']
status_code: 500

2019-11-05 18:37:35,625 - nornir.core.task -    ERROR -      start() - Host 'NXOS-1': task 'push_configs' failed with traceback:
Traceback (most recent call last):
  File "/Library/Frameworks/Python.framework/Versions/3.7/lib/python3.7/site-packages/nornir/core/task.py", line 85, in start
    r = self.task(self, **self.params)
  File "./vlan_mapper.py", line 169, in push_configs
    task.run(task=napalm_configure, configuration=f"configs/{task.host}_ints.txt")
  File "/Library/Frameworks/Python.framework/Versions/3.7/lib/python3.7/site-packages/nornir/core/task.py", line 147, in run
    raise NornirSubTaskError(task=task, result=r)
nornir.core.exceptions.NornirSubTaskError: Subtask: <function napalm_configure at 0x10f492048> (failed)


2019-11-05 18:39:48,701 -  nornir.core -     INFO -        run() - Running task 'netmiko_send_command' with args {'command_string': 'show interface switchport', 'use_textfsm': True} on 2 hosts
2019-11-05 18:39:55,216 -  nornir.core -     INFO -        run() - Running task 'push_configs' with args {} on 2 hosts
2019-11-05 18:40:09,749 - nornir.core.task -    ERROR -      start() - Host 'NXOS-1': task 'napalm_configure' failed with traceback:
Traceback (most recent call last):
  File "/Library/Frameworks/Python.framework/Versions/3.7/lib/python3.7/site-packages/napalm/nxos/nxos.py", line 145, in _commit_merge
    output = self._send_config(self.merge_candidate)
  File "/Library/Frameworks/Python.framework/Versions/3.7/lib/python3.7/site-packages/napalm/nxos/nxos.py", line 652, in _send_config
    return self.device.config_list(commands)
  File "/Library/Frameworks/Python.framework/Versions/3.7/lib/python3.7/site-packages/nxapi_plumbing/device.py", line 126, in config_list
    return self.api._nxapi_command_conf(commands)
  File "/Library/Frameworks/Python.framework/Versions/3.7/lib/python3.7/site-packages/nxapi_plumbing/api_client.py", line 112, in _nxapi_command_conf
    return self._nxapi_command(commands=commands, method=method)
  File "/Library/Frameworks/Python.framework/Versions/3.7/lib/python3.7/site-packages/nxapi_plumbing/api_client.py", line 105, in _nxapi_command
    response = self._send_request(commands, method=method)
  File "/Library/Frameworks/Python.framework/Versions/3.7/lib/python3.7/site-packages/nxapi_plumbing/api_client.py", line 82, in _send_request
    raise NXAPIPostError(msg)
nxapi_plumbing.errors.NXAPIPostError: Invalid status code returned on NX-API POST
commands: ['configs/NXOS-1_ints.txt']
status_code: 500

During handling of the above exception, another exception occurred:

Traceback (most recent call last):
  File "/Library/Frameworks/Python.framework/Versions/3.7/lib/python3.7/site-packages/nornir/core/task.py", line 85, in start
    r = self.task(self, **self.params)
  File "/Library/Frameworks/Python.framework/Versions/3.7/lib/python3.7/site-packages/nornir/plugins/tasks/networking/napalm_configure.py", line 37, in napalm_configure
    device.commit_config()
  File "/Library/Frameworks/Python.framework/Versions/3.7/lib/python3.7/site-packages/napalm/nxos/nxos.py", line 222, in commit_config
    self._commit_merge()
  File "/Library/Frameworks/Python.framework/Versions/3.7/lib/python3.7/site-packages/napalm/nxos/nxos.py", line 151, in _commit_merge
    raise MergeConfigException(str(e))
napalm.base.exceptions.MergeConfigException: Invalid status code returned on NX-API POST
commands: ['configs/NXOS-1_ints.txt']
status_code: 500

2019-11-05 18:40:09,750 - nornir.core.task -    ERROR -      start() - Host 'NXOS-1': task 'push_configs' failed with traceback:
Traceback (most recent call last):
  File "/Library/Frameworks/Python.framework/Versions/3.7/lib/python3.7/site-packages/nornir/core/task.py", line 85, in start
    r = self.task(self, **self.params)
  File "./vlan_mapper.py", line 169, in push_configs
    task.run(task=napalm_configure, configuration=f"configs/{task.host}_ints.txt")
  File "/Library/Frameworks/Python.framework/Versions/3.7/lib/python3.7/site-packages/nornir/core/task.py", line 147, in run
    raise NornirSubTaskError(task=task, result=r)
nornir.core.exceptions.NornirSubTaskError: Subtask: <function napalm_configure at 0x1061ae048> (failed)


2019-11-05 18:40:15,990 - nornir.core.task -    ERROR -      start() - Host 'NXOS-2': task 'napalm_configure' failed with traceback:
Traceback (most recent call last):
  File "/Library/Frameworks/Python.framework/Versions/3.7/lib/python3.7/site-packages/napalm/nxos/nxos.py", line 145, in _commit_merge
    output = self._send_config(self.merge_candidate)
  File "/Library/Frameworks/Python.framework/Versions/3.7/lib/python3.7/site-packages/napalm/nxos/nxos.py", line 652, in _send_config
    return self.device.config_list(commands)
  File "/Library/Frameworks/Python.framework/Versions/3.7/lib/python3.7/site-packages/nxapi_plumbing/device.py", line 126, in config_list
    return self.api._nxapi_command_conf(commands)
  File "/Library/Frameworks/Python.framework/Versions/3.7/lib/python3.7/site-packages/nxapi_plumbing/api_client.py", line 112, in _nxapi_command_conf
    return self._nxapi_command(commands=commands, method=method)
  File "/Library/Frameworks/Python.framework/Versions/3.7/lib/python3.7/site-packages/nxapi_plumbing/api_client.py", line 105, in _nxapi_command
    response = self._send_request(commands, method=method)
  File "/Library/Frameworks/Python.framework/Versions/3.7/lib/python3.7/site-packages/nxapi_plumbing/api_client.py", line 82, in _send_request
    raise NXAPIPostError(msg)
nxapi_plumbing.errors.NXAPIPostError: Invalid status code returned on NX-API POST
commands: ['configs/NXOS-2_ints.txt']
status_code: 500

During handling of the above exception, another exception occurred:

Traceback (most recent call last):
  File "/Library/Frameworks/Python.framework/Versions/3.7/lib/python3.7/site-packages/nornir/core/task.py", line 85, in start
    r = self.task(self, **self.params)
  File "/Library/Frameworks/Python.framework/Versions/3.7/lib/python3.7/site-packages/nornir/plugins/tasks/networking/napalm_configure.py", line 37, in napalm_configure
    device.commit_config()
  File "/Library/Frameworks/Python.framework/Versions/3.7/lib/python3.7/site-packages/napalm/nxos/nxos.py", line 222, in commit_config
    self._commit_merge()
  File "/Library/Frameworks/Python.framework/Versions/3.7/lib/python3.7/site-packages/napalm/nxos/nxos.py", line 151, in _commit_merge
    raise MergeConfigException(str(e))
napalm.base.exceptions.MergeConfigException: Invalid status code returned on NX-API POST
commands: ['configs/NXOS-2_ints.txt']
status_code: 500

2019-11-05 18:40:15,990 - nornir.core.task -    ERROR -      start() - Host 'NXOS-2': task 'push_configs' failed with traceback:
Traceback (most recent call last):
  File "/Library/Frameworks/Python.framework/Versions/3.7/lib/python3.7/site-packages/nornir/core/task.py", line 85, in start
    r = self.task(self, **self.params)
  File "./vlan_mapper.py", line 169, in push_configs
    task.run(task=napalm_configure, configuration=f"configs/{task.host}_ints.txt")
  File "/Library/Frameworks/Python.framework/Versions/3.7/lib/python3.7/site-packages/nornir/core/task.py", line 147, in run
    raise NornirSubTaskError(task=task, result=r)
nornir.core.exceptions.NornirSubTaskError: Subtask: <function napalm_configure at 0x1061ae048> (failed)


2019-11-05 18:41:38,381 -  nornir.core -     INFO -        run() - Running task 'netmiko_send_command' with args {'command_string': 'show interface switchport', 'use_textfsm': True} on 2 hosts
2019-11-05 18:41:45,103 -  nornir.core -     INFO -        run() - Running task 'push_configs' with args {} on 2 hosts
2019-11-05 18:42:00,741 - nornir.core.task -    ERROR -      start() - Host 'NXOS-1': task 'napalm_configure' failed with traceback:
Traceback (most recent call last):
  File "/Library/Frameworks/Python.framework/Versions/3.7/lib/python3.7/site-packages/napalm/nxos/nxos.py", line 145, in _commit_merge
    output = self._send_config(self.merge_candidate)
  File "/Library/Frameworks/Python.framework/Versions/3.7/lib/python3.7/site-packages/napalm/nxos/nxos.py", line 652, in _send_config
    return self.device.config_list(commands)
  File "/Library/Frameworks/Python.framework/Versions/3.7/lib/python3.7/site-packages/nxapi_plumbing/device.py", line 126, in config_list
    return self.api._nxapi_command_conf(commands)
  File "/Library/Frameworks/Python.framework/Versions/3.7/lib/python3.7/site-packages/nxapi_plumbing/api_client.py", line 112, in _nxapi_command_conf
    return self._nxapi_command(commands=commands, method=method)
  File "/Library/Frameworks/Python.framework/Versions/3.7/lib/python3.7/site-packages/nxapi_plumbing/api_client.py", line 105, in _nxapi_command
    response = self._send_request(commands, method=method)
  File "/Library/Frameworks/Python.framework/Versions/3.7/lib/python3.7/site-packages/nxapi_plumbing/api_client.py", line 82, in _send_request
    raise NXAPIPostError(msg)
nxapi_plumbing.errors.NXAPIPostError: Invalid status code returned on NX-API POST
commands: ['interface Ethernet1/1', ' switchport access vlan 110', ' switchport mode access', '!', 'interface Ethernet1/2', ' switchport trunk allowed vlan 300,600,700', ' switchport trunk native vlan 300', ' switchport mode trunk', '!', 'interface Ethernet1/3', ' switchport trunk allowed vlan 300,800,900', ' switchport trunk native vlan 1', ' switchport mode trunk', '!', 'interface Ethernet1/5', ' switchport access vlan 300', ' switchport mode access', '!', 'interface Ethernet1/11', ' switchport access vlan 300', ' switchport mode access', '!']
status_code: 500

During handling of the above exception, another exception occurred:

Traceback (most recent call last):
  File "/Library/Frameworks/Python.framework/Versions/3.7/lib/python3.7/site-packages/nornir/core/task.py", line 85, in start
    r = self.task(self, **self.params)
  File "/Library/Frameworks/Python.framework/Versions/3.7/lib/python3.7/site-packages/nornir/plugins/tasks/networking/napalm_configure.py", line 37, in napalm_configure
    device.commit_config()
  File "/Library/Frameworks/Python.framework/Versions/3.7/lib/python3.7/site-packages/napalm/nxos/nxos.py", line 222, in commit_config
    self._commit_merge()
  File "/Library/Frameworks/Python.framework/Versions/3.7/lib/python3.7/site-packages/napalm/nxos/nxos.py", line 151, in _commit_merge
    raise MergeConfigException(str(e))
napalm.base.exceptions.MergeConfigException: Invalid status code returned on NX-API POST
commands: ['interface Ethernet1/1', ' switchport access vlan 110', ' switchport mode access', '!', 'interface Ethernet1/2', ' switchport trunk allowed vlan 300,600,700', ' switchport trunk native vlan 300', ' switchport mode trunk', '!', 'interface Ethernet1/3', ' switchport trunk allowed vlan 300,800,900', ' switchport trunk native vlan 1', ' switchport mode trunk', '!', 'interface Ethernet1/5', ' switchport access vlan 300', ' switchport mode access', '!', 'interface Ethernet1/11', ' switchport access vlan 300', ' switchport mode access', '!']
status_code: 500

2019-11-05 18:42:00,741 - nornir.core.task -    ERROR -      start() - Host 'NXOS-1': task 'push_configs' failed with traceback:
Traceback (most recent call last):
  File "/Library/Frameworks/Python.framework/Versions/3.7/lib/python3.7/site-packages/nornir/core/task.py", line 85, in start
    r = self.task(self, **self.params)
  File "./vlan_mapper.py", line 169, in push_configs
    task.run(task=napalm_configure, filename=f"configs/{task.host}_ints.txt")
  File "/Library/Frameworks/Python.framework/Versions/3.7/lib/python3.7/site-packages/nornir/core/task.py", line 147, in run
    raise NornirSubTaskError(task=task, result=r)
nornir.core.exceptions.NornirSubTaskError: Subtask: <function napalm_configure at 0x108d6d048> (failed)


2019-11-05 18:42:04,980 - nornir.core.task -    ERROR -      start() - Host 'NXOS-2': task 'napalm_configure' failed with traceback:
Traceback (most recent call last):
  File "/Library/Frameworks/Python.framework/Versions/3.7/lib/python3.7/site-packages/napalm/nxos/nxos.py", line 145, in _commit_merge
    output = self._send_config(self.merge_candidate)
  File "/Library/Frameworks/Python.framework/Versions/3.7/lib/python3.7/site-packages/napalm/nxos/nxos.py", line 652, in _send_config
    return self.device.config_list(commands)
  File "/Library/Frameworks/Python.framework/Versions/3.7/lib/python3.7/site-packages/nxapi_plumbing/device.py", line 126, in config_list
    return self.api._nxapi_command_conf(commands)
  File "/Library/Frameworks/Python.framework/Versions/3.7/lib/python3.7/site-packages/nxapi_plumbing/api_client.py", line 112, in _nxapi_command_conf
    return self._nxapi_command(commands=commands, method=method)
  File "/Library/Frameworks/Python.framework/Versions/3.7/lib/python3.7/site-packages/nxapi_plumbing/api_client.py", line 105, in _nxapi_command
    response = self._send_request(commands, method=method)
  File "/Library/Frameworks/Python.framework/Versions/3.7/lib/python3.7/site-packages/nxapi_plumbing/api_client.py", line 82, in _send_request
    raise NXAPIPostError(msg)
nxapi_plumbing.errors.NXAPIPostError: Invalid status code returned on NX-API POST
commands: ['interface Ethernet1/2', ' switchport access vlan 400', ' switchport mode access', '!', 'interface Ethernet1/4', ' switchport access vlan 400', ' switchport mode access', '!', 'interface Ethernet1/11', ' switchport access vlan 400', ' switchport mode access', '!', 'interface Ethernet1/21', ' switchport access vlan 500', ' switchport mode access', '!', 'interface Ethernet1/25', ' switchport access vlan 500', ' switchport mode access', '!']
status_code: 500

During handling of the above exception, another exception occurred:

Traceback (most recent call last):
  File "/Library/Frameworks/Python.framework/Versions/3.7/lib/python3.7/site-packages/nornir/core/task.py", line 85, in start
    r = self.task(self, **self.params)
  File "/Library/Frameworks/Python.framework/Versions/3.7/lib/python3.7/site-packages/nornir/plugins/tasks/networking/napalm_configure.py", line 37, in napalm_configure
    device.commit_config()
  File "/Library/Frameworks/Python.framework/Versions/3.7/lib/python3.7/site-packages/napalm/nxos/nxos.py", line 222, in commit_config
    self._commit_merge()
  File "/Library/Frameworks/Python.framework/Versions/3.7/lib/python3.7/site-packages/napalm/nxos/nxos.py", line 151, in _commit_merge
    raise MergeConfigException(str(e))
napalm.base.exceptions.MergeConfigException: Invalid status code returned on NX-API POST
commands: ['interface Ethernet1/2', ' switchport access vlan 400', ' switchport mode access', '!', 'interface Ethernet1/4', ' switchport access vlan 400', ' switchport mode access', '!', 'interface Ethernet1/11', ' switchport access vlan 400', ' switchport mode access', '!', 'interface Ethernet1/21', ' switchport access vlan 500', ' switchport mode access', '!', 'interface Ethernet1/25', ' switchport access vlan 500', ' switchport mode access', '!']
status_code: 500

2019-11-05 18:42:04,981 - nornir.core.task -    ERROR -      start() - Host 'NXOS-2': task 'push_configs' failed with traceback:
Traceback (most recent call last):
  File "/Library/Frameworks/Python.framework/Versions/3.7/lib/python3.7/site-packages/nornir/core/task.py", line 85, in start
    r = self.task(self, **self.params)
  File "./vlan_mapper.py", line 169, in push_configs
    task.run(task=napalm_configure, filename=f"configs/{task.host}_ints.txt")
  File "/Library/Frameworks/Python.framework/Versions/3.7/lib/python3.7/site-packages/nornir/core/task.py", line 147, in run
    raise NornirSubTaskError(task=task, result=r)
nornir.core.exceptions.NornirSubTaskError: Subtask: <function napalm_configure at 0x108d6d048> (failed)


2019-11-05 18:42:14,088 -  nornir.core -     INFO -        run() - Running task 'netmiko_send_command' with args {'command_string': 'show interface switchport', 'use_textfsm': True} on 2 hosts
2019-11-05 18:42:20,711 -  nornir.core -     INFO -        run() - Running task 'push_configs' with args {} on 2 hosts
2019-11-05 18:42:20,714 - nornir.core.task -    ERROR -      start() - Host 'NXOS-1': task 'napalm_configure' failed with traceback:
Traceback (most recent call last):
  File "/Library/Frameworks/Python.framework/Versions/3.7/lib/python3.7/site-packages/nornir/core/task.py", line 85, in start
    r = self.task(self, **self.params)
TypeError: napalm_configure() got an unexpected keyword argument 'configuration_file'

2019-11-05 18:42:20,714 - nornir.core.task -    ERROR -      start() - Host 'NXOS-2': task 'napalm_configure' failed with traceback:
Traceback (most recent call last):
  File "/Library/Frameworks/Python.framework/Versions/3.7/lib/python3.7/site-packages/nornir/core/task.py", line 85, in start
    r = self.task(self, **self.params)
TypeError: napalm_configure() got an unexpected keyword argument 'configuration_file'

2019-11-05 18:42:20,715 - nornir.core.task -    ERROR -      start() - Host 'NXOS-1': task 'push_configs' failed with traceback:
Traceback (most recent call last):
  File "/Library/Frameworks/Python.framework/Versions/3.7/lib/python3.7/site-packages/nornir/core/task.py", line 85, in start
    r = self.task(self, **self.params)
  File "./vlan_mapper.py", line 169, in push_configs
    task.run(task=napalm_configure, configuration_file=f"configs/{task.host}_ints.txt")
  File "/Library/Frameworks/Python.framework/Versions/3.7/lib/python3.7/site-packages/nornir/core/task.py", line 147, in run
    raise NornirSubTaskError(task=task, result=r)
nornir.core.exceptions.NornirSubTaskError: Subtask: <function napalm_configure at 0x102eca048> (failed)


2019-11-05 18:42:20,715 - nornir.core.task -    ERROR -      start() - Host 'NXOS-2': task 'push_configs' failed with traceback:
Traceback (most recent call last):
  File "/Library/Frameworks/Python.framework/Versions/3.7/lib/python3.7/site-packages/nornir/core/task.py", line 85, in start
    r = self.task(self, **self.params)
  File "./vlan_mapper.py", line 169, in push_configs
    task.run(task=napalm_configure, configuration_file=f"configs/{task.host}_ints.txt")
  File "/Library/Frameworks/Python.framework/Versions/3.7/lib/python3.7/site-packages/nornir/core/task.py", line 147, in run
    raise NornirSubTaskError(task=task, result=r)
nornir.core.exceptions.NornirSubTaskError: Subtask: <function napalm_configure at 0x102eca048> (failed)


2019-11-05 18:46:12,748 -  nornir.core -     INFO -        run() - Running task 'netmiko_send_command' with args {'command_string': 'show interface switchport', 'use_textfsm': True} on 2 hosts
2019-11-05 18:46:19,206 -  nornir.core -     INFO -        run() - Running task 'push_configs' with args {} on 2 hosts
2019-11-05 18:46:33,947 - nornir.core.task -    ERROR -      start() - Host 'NXOS-1': task 'napalm_configure' failed with traceback:
Traceback (most recent call last):
  File "/Library/Frameworks/Python.framework/Versions/3.7/lib/python3.7/site-packages/napalm/nxos/nxos.py", line 145, in _commit_merge
    output = self._send_config(self.merge_candidate)
  File "/Library/Frameworks/Python.framework/Versions/3.7/lib/python3.7/site-packages/napalm/nxos/nxos.py", line 652, in _send_config
    return self.device.config_list(commands)
  File "/Library/Frameworks/Python.framework/Versions/3.7/lib/python3.7/site-packages/nxapi_plumbing/device.py", line 126, in config_list
    return self.api._nxapi_command_conf(commands)
  File "/Library/Frameworks/Python.framework/Versions/3.7/lib/python3.7/site-packages/nxapi_plumbing/api_client.py", line 112, in _nxapi_command_conf
    return self._nxapi_command(commands=commands, method=method)
  File "/Library/Frameworks/Python.framework/Versions/3.7/lib/python3.7/site-packages/nxapi_plumbing/api_client.py", line 105, in _nxapi_command
    response = self._send_request(commands, method=method)
  File "/Library/Frameworks/Python.framework/Versions/3.7/lib/python3.7/site-packages/nxapi_plumbing/api_client.py", line 82, in _send_request
    raise NXAPIPostError(msg)
nxapi_plumbing.errors.NXAPIPostError: Invalid status code returned on NX-API POST
commands: ['interface Ethernet1/1', ' switchport access vlan 110', ' switchport mode access', '!', 'interface Ethernet1/2', ' switchport trunk allowed vlan 300,600,700', ' switchport trunk native vlan 300', ' switchport mode trunk', '!', 'interface Ethernet1/3', ' switchport trunk allowed vlan 300,800,900', ' switchport trunk native vlan 1', ' switchport mode trunk', '!', 'interface Ethernet1/5', ' switchport access vlan 300', ' switchport mode access', '!', 'interface Ethernet1/11', ' switchport access vlan 300', ' switchport mode access', '!']
status_code: 500

During handling of the above exception, another exception occurred:

Traceback (most recent call last):
  File "/Library/Frameworks/Python.framework/Versions/3.7/lib/python3.7/site-packages/nornir/core/task.py", line 85, in start
    r = self.task(self, **self.params)
  File "/Library/Frameworks/Python.framework/Versions/3.7/lib/python3.7/site-packages/nornir/plugins/tasks/networking/napalm_configure.py", line 37, in napalm_configure
    device.commit_config()
  File "/Library/Frameworks/Python.framework/Versions/3.7/lib/python3.7/site-packages/napalm/nxos/nxos.py", line 222, in commit_config
    self._commit_merge()
  File "/Library/Frameworks/Python.framework/Versions/3.7/lib/python3.7/site-packages/napalm/nxos/nxos.py", line 151, in _commit_merge
    raise MergeConfigException(str(e))
napalm.base.exceptions.MergeConfigException: Invalid status code returned on NX-API POST
commands: ['interface Ethernet1/1', ' switchport access vlan 110', ' switchport mode access', '!', 'interface Ethernet1/2', ' switchport trunk allowed vlan 300,600,700', ' switchport trunk native vlan 300', ' switchport mode trunk', '!', 'interface Ethernet1/3', ' switchport trunk allowed vlan 300,800,900', ' switchport trunk native vlan 1', ' switchport mode trunk', '!', 'interface Ethernet1/5', ' switchport access vlan 300', ' switchport mode access', '!', 'interface Ethernet1/11', ' switchport access vlan 300', ' switchport mode access', '!']
status_code: 500

2019-11-05 18:46:33,947 - nornir.core.task -    ERROR -      start() - Host 'NXOS-1': task 'push_configs' failed with traceback:
Traceback (most recent call last):
  File "/Library/Frameworks/Python.framework/Versions/3.7/lib/python3.7/site-packages/nornir/core/task.py", line 85, in start
    r = self.task(self, **self.params)
  File "./vlan_mapper.py", line 170, in push_configs
    task.run(task=napalm_configure, filename=f"configs/{task.host}_ints.txt")
  File "/Library/Frameworks/Python.framework/Versions/3.7/lib/python3.7/site-packages/nornir/core/task.py", line 147, in run
    raise NornirSubTaskError(task=task, result=r)
nornir.core.exceptions.NornirSubTaskError: Subtask: <function napalm_configure at 0x108524048> (failed)


2019-11-05 18:46:43,651 - nornir.core.task -    ERROR -      start() - Host 'NXOS-2': task 'napalm_configure' failed with traceback:
Traceback (most recent call last):
  File "/Library/Frameworks/Python.framework/Versions/3.7/lib/python3.7/site-packages/napalm/nxos/nxos.py", line 145, in _commit_merge
    output = self._send_config(self.merge_candidate)
  File "/Library/Frameworks/Python.framework/Versions/3.7/lib/python3.7/site-packages/napalm/nxos/nxos.py", line 652, in _send_config
    return self.device.config_list(commands)
  File "/Library/Frameworks/Python.framework/Versions/3.7/lib/python3.7/site-packages/nxapi_plumbing/device.py", line 126, in config_list
    return self.api._nxapi_command_conf(commands)
  File "/Library/Frameworks/Python.framework/Versions/3.7/lib/python3.7/site-packages/nxapi_plumbing/api_client.py", line 112, in _nxapi_command_conf
    return self._nxapi_command(commands=commands, method=method)
  File "/Library/Frameworks/Python.framework/Versions/3.7/lib/python3.7/site-packages/nxapi_plumbing/api_client.py", line 105, in _nxapi_command
    response = self._send_request(commands, method=method)
  File "/Library/Frameworks/Python.framework/Versions/3.7/lib/python3.7/site-packages/nxapi_plumbing/api_client.py", line 82, in _send_request
    raise NXAPIPostError(msg)
nxapi_plumbing.errors.NXAPIPostError: Invalid status code returned on NX-API POST
commands: ['interface Ethernet1/2', ' switchport access vlan 400', ' switchport mode access', '!', 'interface Ethernet1/4', ' switchport access vlan 400', ' switchport mode access', '!', 'interface Ethernet1/11', ' switchport access vlan 400', ' switchport mode access', '!', 'interface Ethernet1/21', ' switchport access vlan 500', ' switchport mode access', '!', 'interface Ethernet1/25', ' switchport access vlan 500', ' switchport mode access', '!']
status_code: 500

During handling of the above exception, another exception occurred:

Traceback (most recent call last):
  File "/Library/Frameworks/Python.framework/Versions/3.7/lib/python3.7/site-packages/nornir/core/task.py", line 85, in start
    r = self.task(self, **self.params)
  File "/Library/Frameworks/Python.framework/Versions/3.7/lib/python3.7/site-packages/nornir/plugins/tasks/networking/napalm_configure.py", line 37, in napalm_configure
    device.commit_config()
  File "/Library/Frameworks/Python.framework/Versions/3.7/lib/python3.7/site-packages/napalm/nxos/nxos.py", line 222, in commit_config
    self._commit_merge()
  File "/Library/Frameworks/Python.framework/Versions/3.7/lib/python3.7/site-packages/napalm/nxos/nxos.py", line 151, in _commit_merge
    raise MergeConfigException(str(e))
napalm.base.exceptions.MergeConfigException: Invalid status code returned on NX-API POST
commands: ['interface Ethernet1/2', ' switchport access vlan 400', ' switchport mode access', '!', 'interface Ethernet1/4', ' switchport access vlan 400', ' switchport mode access', '!', 'interface Ethernet1/11', ' switchport access vlan 400', ' switchport mode access', '!', 'interface Ethernet1/21', ' switchport access vlan 500', ' switchport mode access', '!', 'interface Ethernet1/25', ' switchport access vlan 500', ' switchport mode access', '!']
status_code: 500

2019-11-05 18:46:43,652 - nornir.core.task -    ERROR -      start() - Host 'NXOS-2': task 'push_configs' failed with traceback:
Traceback (most recent call last):
  File "/Library/Frameworks/Python.framework/Versions/3.7/lib/python3.7/site-packages/nornir/core/task.py", line 85, in start
    r = self.task(self, **self.params)
  File "./vlan_mapper.py", line 170, in push_configs
    task.run(task=napalm_configure, filename=f"configs/{task.host}_ints.txt")
  File "/Library/Frameworks/Python.framework/Versions/3.7/lib/python3.7/site-packages/nornir/core/task.py", line 147, in run
    raise NornirSubTaskError(task=task, result=r)
nornir.core.exceptions.NornirSubTaskError: Subtask: <function napalm_configure at 0x108524048> (failed)


2019-11-05 18:54:33,693 -  nornir.core -     INFO -        run() - Running task 'netmiko_send_command' with args {'command_string': 'show interface switchport', 'use_textfsm': True} on 2 hosts
2019-11-05 18:54:40,298 -  nornir.core -     INFO -        run() - Running task 'push_configs' with args {} on 2 hosts
2019-11-05 18:54:41,010 - nornir.core.task -    ERROR -      start() - Host 'NXOS-1': task 'napalm_configure' failed with traceback:
Traceback (most recent call last):
  File "/Library/Frameworks/Python.framework/Versions/3.7/lib/python3.7/site-packages/urllib3-1.24.2-py3.7.egg/urllib3/contrib/pyopenssl.py", line 456, in wrap_socket
    cnx.do_handshake()
  File "/Library/Frameworks/Python.framework/Versions/3.7/lib/python3.7/site-packages/OpenSSL/SSL.py", line 1915, in do_handshake
    self._raise_ssl_error(self._ssl, result)
  File "/Library/Frameworks/Python.framework/Versions/3.7/lib/python3.7/site-packages/OpenSSL/SSL.py", line 1647, in _raise_ssl_error
    _raise_current_error()
  File "/Library/Frameworks/Python.framework/Versions/3.7/lib/python3.7/site-packages/OpenSSL/_util.py", line 54, in exception_from_error_queue
    raise exception_type(errors)
OpenSSL.SSL.Error: [('SSL routines', 'ssl3_get_record', 'wrong version number')]

During handling of the above exception, another exception occurred:

Traceback (most recent call last):
  File "/Library/Frameworks/Python.framework/Versions/3.7/lib/python3.7/site-packages/urllib3-1.24.2-py3.7.egg/urllib3/connectionpool.py", line 600, in urlopen
    chunked=chunked)
  File "/Library/Frameworks/Python.framework/Versions/3.7/lib/python3.7/site-packages/urllib3-1.24.2-py3.7.egg/urllib3/connectionpool.py", line 343, in _make_request
    self._validate_conn(conn)
  File "/Library/Frameworks/Python.framework/Versions/3.7/lib/python3.7/site-packages/urllib3-1.24.2-py3.7.egg/urllib3/connectionpool.py", line 839, in _validate_conn
    conn.connect()
  File "/Library/Frameworks/Python.framework/Versions/3.7/lib/python3.7/site-packages/urllib3-1.24.2-py3.7.egg/urllib3/connection.py", line 344, in connect
    ssl_context=context)
  File "/Library/Frameworks/Python.framework/Versions/3.7/lib/python3.7/site-packages/urllib3-1.24.2-py3.7.egg/urllib3/util/ssl_.py", line 360, in ssl_wrap_socket
    return context.wrap_socket(sock)
  File "/Library/Frameworks/Python.framework/Versions/3.7/lib/python3.7/site-packages/urllib3-1.24.2-py3.7.egg/urllib3/contrib/pyopenssl.py", line 462, in wrap_socket
    raise ssl.SSLError('bad handshake: %r' % e)
ssl.SSLError: ("bad handshake: Error([('SSL routines', 'ssl3_get_record', 'wrong version number')])",)

During handling of the above exception, another exception occurred:

Traceback (most recent call last):
  File "/Library/Frameworks/Python.framework/Versions/3.7/lib/python3.7/site-packages/requests-2.21.0-py3.7.egg/requests/adapters.py", line 449, in send
    timeout=timeout
  File "/Library/Frameworks/Python.framework/Versions/3.7/lib/python3.7/site-packages/urllib3-1.24.2-py3.7.egg/urllib3/connectionpool.py", line 638, in urlopen
    _stacktrace=sys.exc_info()[2])
  File "/Library/Frameworks/Python.framework/Versions/3.7/lib/python3.7/site-packages/urllib3-1.24.2-py3.7.egg/urllib3/util/retry.py", line 399, in increment
    raise MaxRetryError(_pool, url, error or ResponseError(cause))
urllib3.exceptions.MaxRetryError: HTTPSConnectionPool(host='172.20.58.61', port=22): Max retries exceeded with url: /ins (Caused by SSLError(SSLError("bad handshake: Error([('SSL routines', 'ssl3_get_record', 'wrong version number')])")))

During handling of the above exception, another exception occurred:

Traceback (most recent call last):
  File "/Library/Frameworks/Python.framework/Versions/3.7/lib/python3.7/site-packages/nxapi_plumbing/api_client.py", line 64, in _send_request
    verify=self.verify,
  File "/Library/Frameworks/Python.framework/Versions/3.7/lib/python3.7/site-packages/requests-2.21.0-py3.7.egg/requests/api.py", line 116, in post
    return request('post', url, data=data, json=json, **kwargs)
  File "/Library/Frameworks/Python.framework/Versions/3.7/lib/python3.7/site-packages/requests-2.21.0-py3.7.egg/requests/api.py", line 60, in request
    return session.request(method=method, url=url, **kwargs)
  File "/Library/Frameworks/Python.framework/Versions/3.7/lib/python3.7/site-packages/requests-2.21.0-py3.7.egg/requests/sessions.py", line 533, in request
    resp = self.send(prep, **send_kwargs)
  File "/Library/Frameworks/Python.framework/Versions/3.7/lib/python3.7/site-packages/requests-2.21.0-py3.7.egg/requests/sessions.py", line 646, in send
    r = adapter.send(request, **kwargs)
  File "/Library/Frameworks/Python.framework/Versions/3.7/lib/python3.7/site-packages/requests-2.21.0-py3.7.egg/requests/adapters.py", line 514, in send
    raise SSLError(e, request=request)
requests.exceptions.SSLError: HTTPSConnectionPool(host='172.20.58.61', port=22): Max retries exceeded with url: /ins (Caused by SSLError(SSLError("bad handshake: Error([('SSL routines', 'ssl3_get_record', 'wrong version number')])")))

During handling of the above exception, another exception occurred:

Traceback (most recent call last):
  File "/Library/Frameworks/Python.framework/Versions/3.7/lib/python3.7/site-packages/napalm/nxos/nxos.py", line 629, in open
    self._send_command("show hostname")
  File "/Library/Frameworks/Python.framework/Versions/3.7/lib/python3.7/site-packages/napalm/nxos/nxos.py", line 643, in _send_command
    return self.device.show(command, raw_text=raw_text)
  File "/Library/Frameworks/Python.framework/Versions/3.7/lib/python3.7/site-packages/nxapi_plumbing/device.py", line 61, in show
    result = self.show_list(commands, raw_text)
  File "/Library/Frameworks/Python.framework/Versions/3.7/lib/python3.7/site-packages/nxapi_plumbing/device.py", line 89, in show_list
    return self.api._nxapi_command(commands, method=cmd_method)
  File "/Library/Frameworks/Python.framework/Versions/3.7/lib/python3.7/site-packages/nxapi_plumbing/api_client.py", line 105, in _nxapi_command
    response = self._send_request(commands, method=method)
  File "/Library/Frameworks/Python.framework/Versions/3.7/lib/python3.7/site-packages/nxapi_plumbing/api_client.py", line 67, in _send_request
    raise NXAPIConnectionError(str(e))
nxapi_plumbing.errors.NXAPIConnectionError: HTTPSConnectionPool(host='172.20.58.61', port=22): Max retries exceeded with url: /ins (Caused by SSLError(SSLError("bad handshake: Error([('SSL routines', 'ssl3_get_record', 'wrong version number')])")))

During handling of the above exception, another exception occurred:

Traceback (most recent call last):
  File "/Library/Frameworks/Python.framework/Versions/3.7/lib/python3.7/site-packages/nornir/core/task.py", line 85, in start
    r = self.task(self, **self.params)
  File "/Library/Frameworks/Python.framework/Versions/3.7/lib/python3.7/site-packages/nornir/plugins/tasks/networking/napalm_configure.py", line 27, in napalm_configure
    device = task.host.get_connection("napalm", task.nornir.config)
  File "/Library/Frameworks/Python.framework/Versions/3.7/lib/python3.7/site-packages/nornir/core/inventory.py", line 302, in get_connection
    extras=conn.extras,
  File "/Library/Frameworks/Python.framework/Versions/3.7/lib/python3.7/site-packages/nornir/core/inventory.py", line 352, in open_connection
    configuration=configuration,
  File "/Library/Frameworks/Python.framework/Versions/3.7/lib/python3.7/site-packages/nornir/plugins/connections/napalm.py", line 51, in open
    connection.open()
  File "/Library/Frameworks/Python.framework/Versions/3.7/lib/python3.7/site-packages/napalm/nxos/nxos.py", line 632, in open
    raise ConnectionException("Cannot connect to {}".format(self.hostname))
napalm.base.exceptions.ConnectionException: Cannot connect to 172.20.58.61

2019-11-05 18:54:41,011 - nornir.core.task -    ERROR -      start() - Host 'NXOS-2': task 'napalm_configure' failed with traceback:
Traceback (most recent call last):
  File "/Library/Frameworks/Python.framework/Versions/3.7/lib/python3.7/site-packages/urllib3-1.24.2-py3.7.egg/urllib3/contrib/pyopenssl.py", line 456, in wrap_socket
    cnx.do_handshake()
  File "/Library/Frameworks/Python.framework/Versions/3.7/lib/python3.7/site-packages/OpenSSL/SSL.py", line 1915, in do_handshake
    self._raise_ssl_error(self._ssl, result)
  File "/Library/Frameworks/Python.framework/Versions/3.7/lib/python3.7/site-packages/OpenSSL/SSL.py", line 1647, in _raise_ssl_error
    _raise_current_error()
  File "/Library/Frameworks/Python.framework/Versions/3.7/lib/python3.7/site-packages/OpenSSL/_util.py", line 54, in exception_from_error_queue
    raise exception_type(errors)
OpenSSL.SSL.Error: [('SSL routines', 'ssl3_get_record', 'wrong version number')]

During handling of the above exception, another exception occurred:

Traceback (most recent call last):
  File "/Library/Frameworks/Python.framework/Versions/3.7/lib/python3.7/site-packages/urllib3-1.24.2-py3.7.egg/urllib3/connectionpool.py", line 600, in urlopen
    chunked=chunked)
  File "/Library/Frameworks/Python.framework/Versions/3.7/lib/python3.7/site-packages/urllib3-1.24.2-py3.7.egg/urllib3/connectionpool.py", line 343, in _make_request
    self._validate_conn(conn)
  File "/Library/Frameworks/Python.framework/Versions/3.7/lib/python3.7/site-packages/urllib3-1.24.2-py3.7.egg/urllib3/connectionpool.py", line 839, in _validate_conn
    conn.connect()
  File "/Library/Frameworks/Python.framework/Versions/3.7/lib/python3.7/site-packages/urllib3-1.24.2-py3.7.egg/urllib3/connection.py", line 344, in connect
    ssl_context=context)
  File "/Library/Frameworks/Python.framework/Versions/3.7/lib/python3.7/site-packages/urllib3-1.24.2-py3.7.egg/urllib3/util/ssl_.py", line 360, in ssl_wrap_socket
    return context.wrap_socket(sock)
  File "/Library/Frameworks/Python.framework/Versions/3.7/lib/python3.7/site-packages/urllib3-1.24.2-py3.7.egg/urllib3/contrib/pyopenssl.py", line 462, in wrap_socket
    raise ssl.SSLError('bad handshake: %r' % e)
ssl.SSLError: ("bad handshake: Error([('SSL routines', 'ssl3_get_record', 'wrong version number')])",)

During handling of the above exception, another exception occurred:

Traceback (most recent call last):
  File "/Library/Frameworks/Python.framework/Versions/3.7/lib/python3.7/site-packages/requests-2.21.0-py3.7.egg/requests/adapters.py", line 449, in send
    timeout=timeout
  File "/Library/Frameworks/Python.framework/Versions/3.7/lib/python3.7/site-packages/urllib3-1.24.2-py3.7.egg/urllib3/connectionpool.py", line 638, in urlopen
    _stacktrace=sys.exc_info()[2])
  File "/Library/Frameworks/Python.framework/Versions/3.7/lib/python3.7/site-packages/urllib3-1.24.2-py3.7.egg/urllib3/util/retry.py", line 399, in increment
    raise MaxRetryError(_pool, url, error or ResponseError(cause))
urllib3.exceptions.MaxRetryError: HTTPSConnectionPool(host='172.20.58.62', port=22): Max retries exceeded with url: /ins (Caused by SSLError(SSLError("bad handshake: Error([('SSL routines', 'ssl3_get_record', 'wrong version number')])")))

During handling of the above exception, another exception occurred:

Traceback (most recent call last):
  File "/Library/Frameworks/Python.framework/Versions/3.7/lib/python3.7/site-packages/nxapi_plumbing/api_client.py", line 64, in _send_request
    verify=self.verify,
  File "/Library/Frameworks/Python.framework/Versions/3.7/lib/python3.7/site-packages/requests-2.21.0-py3.7.egg/requests/api.py", line 116, in post
    return request('post', url, data=data, json=json, **kwargs)
  File "/Library/Frameworks/Python.framework/Versions/3.7/lib/python3.7/site-packages/requests-2.21.0-py3.7.egg/requests/api.py", line 60, in request
    return session.request(method=method, url=url, **kwargs)
  File "/Library/Frameworks/Python.framework/Versions/3.7/lib/python3.7/site-packages/requests-2.21.0-py3.7.egg/requests/sessions.py", line 533, in request
    resp = self.send(prep, **send_kwargs)
  File "/Library/Frameworks/Python.framework/Versions/3.7/lib/python3.7/site-packages/requests-2.21.0-py3.7.egg/requests/sessions.py", line 646, in send
    r = adapter.send(request, **kwargs)
  File "/Library/Frameworks/Python.framework/Versions/3.7/lib/python3.7/site-packages/requests-2.21.0-py3.7.egg/requests/adapters.py", line 514, in send
    raise SSLError(e, request=request)
requests.exceptions.SSLError: HTTPSConnectionPool(host='172.20.58.62', port=22): Max retries exceeded with url: /ins (Caused by SSLError(SSLError("bad handshake: Error([('SSL routines', 'ssl3_get_record', 'wrong version number')])")))

During handling of the above exception, another exception occurred:

Traceback (most recent call last):
  File "/Library/Frameworks/Python.framework/Versions/3.7/lib/python3.7/site-packages/napalm/nxos/nxos.py", line 629, in open
    self._send_command("show hostname")
  File "/Library/Frameworks/Python.framework/Versions/3.7/lib/python3.7/site-packages/napalm/nxos/nxos.py", line 643, in _send_command
    return self.device.show(command, raw_text=raw_text)
  File "/Library/Frameworks/Python.framework/Versions/3.7/lib/python3.7/site-packages/nxapi_plumbing/device.py", line 61, in show
    result = self.show_list(commands, raw_text)
  File "/Library/Frameworks/Python.framework/Versions/3.7/lib/python3.7/site-packages/nxapi_plumbing/device.py", line 89, in show_list
    return self.api._nxapi_command(commands, method=cmd_method)
  File "/Library/Frameworks/Python.framework/Versions/3.7/lib/python3.7/site-packages/nxapi_plumbing/api_client.py", line 105, in _nxapi_command
    response = self._send_request(commands, method=method)
  File "/Library/Frameworks/Python.framework/Versions/3.7/lib/python3.7/site-packages/nxapi_plumbing/api_client.py", line 67, in _send_request
    raise NXAPIConnectionError(str(e))
nxapi_plumbing.errors.NXAPIConnectionError: HTTPSConnectionPool(host='172.20.58.62', port=22): Max retries exceeded with url: /ins (Caused by SSLError(SSLError("bad handshake: Error([('SSL routines', 'ssl3_get_record', 'wrong version number')])")))

During handling of the above exception, another exception occurred:

Traceback (most recent call last):
  File "/Library/Frameworks/Python.framework/Versions/3.7/lib/python3.7/site-packages/nornir/core/task.py", line 85, in start
    r = self.task(self, **self.params)
  File "/Library/Frameworks/Python.framework/Versions/3.7/lib/python3.7/site-packages/nornir/plugins/tasks/networking/napalm_configure.py", line 27, in napalm_configure
    device = task.host.get_connection("napalm", task.nornir.config)
  File "/Library/Frameworks/Python.framework/Versions/3.7/lib/python3.7/site-packages/nornir/core/inventory.py", line 302, in get_connection
    extras=conn.extras,
  File "/Library/Frameworks/Python.framework/Versions/3.7/lib/python3.7/site-packages/nornir/core/inventory.py", line 352, in open_connection
    configuration=configuration,
  File "/Library/Frameworks/Python.framework/Versions/3.7/lib/python3.7/site-packages/nornir/plugins/connections/napalm.py", line 51, in open
    connection.open()
  File "/Library/Frameworks/Python.framework/Versions/3.7/lib/python3.7/site-packages/napalm/nxos/nxos.py", line 632, in open
    raise ConnectionException("Cannot connect to {}".format(self.hostname))
napalm.base.exceptions.ConnectionException: Cannot connect to 172.20.58.62

2019-11-05 18:54:41,012 - nornir.core.task -    ERROR -      start() - Host 'NXOS-1': task 'push_configs' failed with traceback:
Traceback (most recent call last):
  File "/Library/Frameworks/Python.framework/Versions/3.7/lib/python3.7/site-packages/nornir/core/task.py", line 85, in start
    r = self.task(self, **self.params)
  File "./vlan_mapper.py", line 170, in push_configs
    task.run(task=napalm_configure, filename=f"configs/{task.host}_ints.txt")
  File "/Library/Frameworks/Python.framework/Versions/3.7/lib/python3.7/site-packages/nornir/core/task.py", line 147, in run
    raise NornirSubTaskError(task=task, result=r)
nornir.core.exceptions.NornirSubTaskError: Subtask: <function napalm_configure at 0x10e842048> (failed)


2019-11-05 18:54:41,012 - nornir.core.task -    ERROR -      start() - Host 'NXOS-2': task 'push_configs' failed with traceback:
Traceback (most recent call last):
  File "/Library/Frameworks/Python.framework/Versions/3.7/lib/python3.7/site-packages/nornir/core/task.py", line 85, in start
    r = self.task(self, **self.params)
  File "./vlan_mapper.py", line 170, in push_configs
    task.run(task=napalm_configure, filename=f"configs/{task.host}_ints.txt")
  File "/Library/Frameworks/Python.framework/Versions/3.7/lib/python3.7/site-packages/nornir/core/task.py", line 147, in run
    raise NornirSubTaskError(task=task, result=r)
nornir.core.exceptions.NornirSubTaskError: Subtask: <function napalm_configure at 0x10e842048> (failed)


2019-11-05 18:58:22,491 -  nornir.core -     INFO -        run() - Running task 'netmiko_send_command' with args {'command_string': 'show interface switchport', 'use_textfsm': True} on 2 hosts
2019-11-05 18:58:28,982 -  nornir.core -     INFO -        run() - Running task 'push_configs' with args {} on 2 hosts
2019-11-05 21:00:49,385 -  nornir.core -     INFO -        run() - Running task 'netmiko_send_command' with args {'command_string': 'show interface switchport', 'use_textfsm': True} on 2 hosts
2019-11-05 21:00:55,898 -  nornir.core -     INFO -        run() - Running task 'push_configs' with args {} on 2 hosts
2019-11-05 21:08:26,792 -  nornir.core -     INFO -        run() - Running task 'netmiko_send_command' with args {'command_string': 'show interface switchport', 'use_textfsm': True} on 2 hosts
2019-11-05 21:08:33,911 -  nornir.core -     INFO -        run() - Running task 'push_configs' with args {} on 2 hosts
2019-11-05 21:08:33,914 - nornir.core.task -    ERROR -      start() - Host 'NXOS-1': task 'push_configs' failed with traceback:
Traceback (most recent call last):
  File "/Library/Frameworks/Python.framework/Versions/3.7/lib/python3.7/site-packages/nornir/core/task.py", line 85, in start
    r = self.task(self, **self.params)
  File "./vlan_mapper.py", line 169, in push_configs
    task.run(task=napalm_configure, config_file=f"configs/{task.host}_ints.txt")
NameError: name 'napalm_configure' is not defined

2019-11-05 21:08:33,914 - nornir.core.task -    ERROR -      start() - Host 'NXOS-2': task 'push_configs' failed with traceback:
Traceback (most recent call last):
  File "/Library/Frameworks/Python.framework/Versions/3.7/lib/python3.7/site-packages/nornir/core/task.py", line 85, in start
    r = self.task(self, **self.params)
  File "./vlan_mapper.py", line 169, in push_configs
    task.run(task=napalm_configure, config_file=f"configs/{task.host}_ints.txt")
NameError: name 'napalm_configure' is not defined

2019-11-05 21:08:49,284 -  nornir.core -     INFO -        run() - Running task 'netmiko_send_command' with args {'command_string': 'show interface switchport', 'use_textfsm': True} on 2 hosts
2019-11-05 21:08:55,880 -  nornir.core -     INFO -        run() - Running task 'push_configs' with args {} on 2 hosts
2019-11-05 21:09:52,680 -  nornir.core -     INFO -        run() - Running task 'netmiko_send_command' with args {'command_string': 'show interface switchport', 'use_textfsm': True} on 2 hosts
2019-11-05 21:09:59,200 -  nornir.core -     INFO -        run() - Running task 'push_configs' with args {} on 2 hosts
2019-11-05 21:10:59,155 -  nornir.core -     INFO -        run() - Running task 'netmiko_send_command' with args {'command_string': 'show interface switchport', 'use_textfsm': True} on 2 hosts
2019-11-05 21:11:05,763 -  nornir.core -     INFO -        run() - Running task 'push_configs' with args {} on 2 hosts
2019-11-05 21:11:46,587 -  nornir.core -     INFO -        run() - Running task 'netmiko_send_command' with args {'command_string': 'show interface switchport', 'use_textfsm': True} on 2 hosts
2019-11-05 21:11:53,229 -  nornir.core -     INFO -        run() - Running task 'push_configs' with args {} on 2 hosts
2019-11-05 21:12:47,226 -  nornir.core -     INFO -        run() - Running task 'netmiko_send_command' with args {'command_string': 'show interface switchport', 'use_textfsm': True} on 2 hosts
2019-11-05 21:12:53,839 -  nornir.core -     INFO -        run() - Running task 'push_configs' with args {} on 2 hosts
2019-11-09 16:22:19,334 -  nornir.core -     INFO -        run() - Running task 'netmiko_send_command' with args {'command_string': 'show interface switchport', 'use_textfsm': True} on 2 hosts
2019-11-09 16:22:26,742 - nornir.core.task -    ERROR -      start() - Host 'NXOS-1': task 'netmiko_send_command' failed with traceback:
Traceback (most recent call last):
  File "/usr/local/lib/python3.7/site-packages/nornir/core/task.py", line 85, in start
    r = self.task(self, **self.params)
  File "/usr/local/lib/python3.7/site-packages/nornir/plugins/tasks/networking/netmiko_send_command.py", line 32, in netmiko_send_command
    result = net_connect.send_command(command_string, **kwargs)
  File "/usr/local/lib/python3.7/site-packages/netmiko/base_connection.py", line 1355, in send_command
    output, platform=self.device_type, command=command_string.strip()
  File "/usr/local/lib/python3.7/site-packages/netmiko/utilities.py", line 262, in get_structured_data
    template_dir = get_template_dir()
  File "/usr/local/lib/python3.7/site-packages/netmiko/utilities.py", line 245, in get_template_dir
    raise ValueError(msg)
ValueError: 
Valid ntc-templates not found, please install https://github.com/networktocode/ntc-templates
and then set the NET_TEXTFSM environment variable to point to the ./ntc-templates/templates
directory.

2019-11-09 16:22:26,931 - nornir.core.task -    ERROR -      start() - Host 'NXOS-2': task 'netmiko_send_command' failed with traceback:
Traceback (most recent call last):
  File "/usr/local/lib/python3.7/site-packages/nornir/core/task.py", line 85, in start
    r = self.task(self, **self.params)
  File "/usr/local/lib/python3.7/site-packages/nornir/plugins/tasks/networking/netmiko_send_command.py", line 32, in netmiko_send_command
    result = net_connect.send_command(command_string, **kwargs)
  File "/usr/local/lib/python3.7/site-packages/netmiko/base_connection.py", line 1355, in send_command
    output, platform=self.device_type, command=command_string.strip()
  File "/usr/local/lib/python3.7/site-packages/netmiko/utilities.py", line 262, in get_structured_data
    template_dir = get_template_dir()
  File "/usr/local/lib/python3.7/site-packages/netmiko/utilities.py", line 245, in get_template_dir
    raise ValueError(msg)
ValueError: 
Valid ntc-templates not found, please install https://github.com/networktocode/ntc-templates
and then set the NET_TEXTFSM environment variable to point to the ./ntc-templates/templates
directory.

2019-11-09 16:23:16,897 -  nornir.core -     INFO -        run() - Running task 'netmiko_send_command' with args {'command_string': 'show interface switchport', 'use_textfsm': True} on 2 hosts
2019-11-09 16:23:23,185 - nornir.core.task -    ERROR -      start() - Host 'NXOS-1': task 'netmiko_send_command' failed with traceback:
Traceback (most recent call last):
  File "/usr/local/lib/python3.7/site-packages/nornir/core/task.py", line 85, in start
    r = self.task(self, **self.params)
  File "/usr/local/lib/python3.7/site-packages/nornir/plugins/tasks/networking/netmiko_send_command.py", line 32, in netmiko_send_command
    result = net_connect.send_command(command_string, **kwargs)
  File "/usr/local/lib/python3.7/site-packages/netmiko/base_connection.py", line 1355, in send_command
    output, platform=self.device_type, command=command_string.strip()
  File "/usr/local/lib/python3.7/site-packages/netmiko/utilities.py", line 262, in get_structured_data
    template_dir = get_template_dir()
  File "/usr/local/lib/python3.7/site-packages/netmiko/utilities.py", line 245, in get_template_dir
    raise ValueError(msg)
ValueError: 
Valid ntc-templates not found, please install https://github.com/networktocode/ntc-templates
and then set the NET_TEXTFSM environment variable to point to the ./ntc-templates/templates
directory.

2019-11-09 16:23:23,394 - nornir.core.task -    ERROR -      start() - Host 'NXOS-2': task 'netmiko_send_command' failed with traceback:
Traceback (most recent call last):
  File "/usr/local/lib/python3.7/site-packages/nornir/core/task.py", line 85, in start
    r = self.task(self, **self.params)
  File "/usr/local/lib/python3.7/site-packages/nornir/plugins/tasks/networking/netmiko_send_command.py", line 32, in netmiko_send_command
    result = net_connect.send_command(command_string, **kwargs)
  File "/usr/local/lib/python3.7/site-packages/netmiko/base_connection.py", line 1355, in send_command
    output, platform=self.device_type, command=command_string.strip()
  File "/usr/local/lib/python3.7/site-packages/netmiko/utilities.py", line 262, in get_structured_data
    template_dir = get_template_dir()
  File "/usr/local/lib/python3.7/site-packages/netmiko/utilities.py", line 245, in get_template_dir
    raise ValueError(msg)
ValueError: 
Valid ntc-templates not found, please install https://github.com/networktocode/ntc-templates
and then set the NET_TEXTFSM environment variable to point to the ./ntc-templates/templates
directory.

2019-11-09 16:26:49,826 -  nornir.core -     INFO -        run() - Running task 'netmiko_send_command' with args {'command_string': 'show interface switchport', 'use_textfsm': True} on 2 hosts
2019-11-09 16:26:56,265 - nornir.core.task -    ERROR -      start() - Host 'NXOS-1': task 'netmiko_send_command' failed with traceback:
Traceback (most recent call last):
  File "/usr/local/lib/python3.7/site-packages/nornir/core/task.py", line 85, in start
    r = self.task(self, **self.params)
  File "/usr/local/lib/python3.7/site-packages/nornir/plugins/tasks/networking/netmiko_send_command.py", line 32, in netmiko_send_command
    result = net_connect.send_command(command_string, **kwargs)
  File "/usr/local/lib/python3.7/site-packages/netmiko/base_connection.py", line 1355, in send_command
    output, platform=self.device_type, command=command_string.strip()
  File "/usr/local/lib/python3.7/site-packages/netmiko/utilities.py", line 262, in get_structured_data
    template_dir = get_template_dir()
  File "/usr/local/lib/python3.7/site-packages/netmiko/utilities.py", line 245, in get_template_dir
    raise ValueError(msg)
ValueError: 
Valid ntc-templates not found, please install https://github.com/networktocode/ntc-templates
and then set the NET_TEXTFSM environment variable to point to the ./ntc-templates/templates
directory.

2019-11-09 16:26:56,265 - nornir.core.task -    ERROR -      start() - Host 'NXOS-2': task 'netmiko_send_command' failed with traceback:
Traceback (most recent call last):
  File "/usr/local/lib/python3.7/site-packages/nornir/core/task.py", line 85, in start
    r = self.task(self, **self.params)
  File "/usr/local/lib/python3.7/site-packages/nornir/plugins/tasks/networking/netmiko_send_command.py", line 32, in netmiko_send_command
    result = net_connect.send_command(command_string, **kwargs)
  File "/usr/local/lib/python3.7/site-packages/netmiko/base_connection.py", line 1355, in send_command
    output, platform=self.device_type, command=command_string.strip()
  File "/usr/local/lib/python3.7/site-packages/netmiko/utilities.py", line 262, in get_structured_data
    template_dir = get_template_dir()
  File "/usr/local/lib/python3.7/site-packages/netmiko/utilities.py", line 245, in get_template_dir
    raise ValueError(msg)
ValueError: 
Valid ntc-templates not found, please install https://github.com/networktocode/ntc-templates
and then set the NET_TEXTFSM environment variable to point to the ./ntc-templates/templates
directory.

2019-11-09 16:27:41,697 -  nornir.core -     INFO -        run() - Running task 'netmiko_send_command' with args {'command_string': 'show interface switchport', 'use_textfsm': True} on 2 hosts
2019-11-09 16:27:47,940 - nornir.core.task -    ERROR -      start() - Host 'NXOS-2': task 'netmiko_send_command' failed with traceback:
Traceback (most recent call last):
  File "/usr/local/lib/python3.7/site-packages/nornir/core/task.py", line 85, in start
    r = self.task(self, **self.params)
  File "/usr/local/lib/python3.7/site-packages/nornir/plugins/tasks/networking/netmiko_send_command.py", line 32, in netmiko_send_command
    result = net_connect.send_command(command_string, **kwargs)
  File "/usr/local/lib/python3.7/site-packages/netmiko/base_connection.py", line 1355, in send_command
    output, platform=self.device_type, command=command_string.strip()
  File "/usr/local/lib/python3.7/site-packages/netmiko/utilities.py", line 262, in get_structured_data
    template_dir = get_template_dir()
  File "/usr/local/lib/python3.7/site-packages/netmiko/utilities.py", line 245, in get_template_dir
    raise ValueError(msg)
ValueError: 
Valid ntc-templates not found, please install https://github.com/networktocode/ntc-templates
and then set the NET_TEXTFSM environment variable to point to the ./ntc-templates/templates
directory.

2019-11-09 16:27:47,940 - nornir.core.task -    ERROR -      start() - Host 'NXOS-1': task 'netmiko_send_command' failed with traceback:
Traceback (most recent call last):
  File "/usr/local/lib/python3.7/site-packages/nornir/core/task.py", line 85, in start
    r = self.task(self, **self.params)
  File "/usr/local/lib/python3.7/site-packages/nornir/plugins/tasks/networking/netmiko_send_command.py", line 32, in netmiko_send_command
    result = net_connect.send_command(command_string, **kwargs)
  File "/usr/local/lib/python3.7/site-packages/netmiko/base_connection.py", line 1355, in send_command
    output, platform=self.device_type, command=command_string.strip()
  File "/usr/local/lib/python3.7/site-packages/netmiko/utilities.py", line 262, in get_structured_data
    template_dir = get_template_dir()
  File "/usr/local/lib/python3.7/site-packages/netmiko/utilities.py", line 245, in get_template_dir
    raise ValueError(msg)
ValueError: 
Valid ntc-templates not found, please install https://github.com/networktocode/ntc-templates
and then set the NET_TEXTFSM environment variable to point to the ./ntc-templates/templates
directory.

2019-11-09 16:27:55,289 -  nornir.core -     INFO -        run() - Running task 'netmiko_send_command' with args {'command_string': 'show interface switchport', 'use_textfsm': True} on 2 hosts
2019-11-09 16:28:01,715 - nornir.core.task -    ERROR -      start() - Host 'NXOS-1': task 'netmiko_send_command' failed with traceback:
Traceback (most recent call last):
  File "/usr/local/lib/python3.7/site-packages/nornir/core/task.py", line 85, in start
    r = self.task(self, **self.params)
  File "/usr/local/lib/python3.7/site-packages/nornir/plugins/tasks/networking/netmiko_send_command.py", line 32, in netmiko_send_command
    result = net_connect.send_command(command_string, **kwargs)
  File "/usr/local/lib/python3.7/site-packages/netmiko/base_connection.py", line 1355, in send_command
    output, platform=self.device_type, command=command_string.strip()
  File "/usr/local/lib/python3.7/site-packages/netmiko/utilities.py", line 262, in get_structured_data
    template_dir = get_template_dir()
  File "/usr/local/lib/python3.7/site-packages/netmiko/utilities.py", line 245, in get_template_dir
    raise ValueError(msg)
ValueError: 
Valid ntc-templates not found, please install https://github.com/networktocode/ntc-templates
and then set the NET_TEXTFSM environment variable to point to the ./ntc-templates/templates
directory.

2019-11-09 16:28:01,716 - nornir.core.task -    ERROR -      start() - Host 'NXOS-2': task 'netmiko_send_command' failed with traceback:
Traceback (most recent call last):
  File "/usr/local/lib/python3.7/site-packages/nornir/core/task.py", line 85, in start
    r = self.task(self, **self.params)
  File "/usr/local/lib/python3.7/site-packages/nornir/plugins/tasks/networking/netmiko_send_command.py", line 32, in netmiko_send_command
    result = net_connect.send_command(command_string, **kwargs)
  File "/usr/local/lib/python3.7/site-packages/netmiko/base_connection.py", line 1355, in send_command
    output, platform=self.device_type, command=command_string.strip()
  File "/usr/local/lib/python3.7/site-packages/netmiko/utilities.py", line 262, in get_structured_data
    template_dir = get_template_dir()
  File "/usr/local/lib/python3.7/site-packages/netmiko/utilities.py", line 245, in get_template_dir
    raise ValueError(msg)
ValueError: 
Valid ntc-templates not found, please install https://github.com/networktocode/ntc-templates
and then set the NET_TEXTFSM environment variable to point to the ./ntc-templates/templates
directory.

2019-11-09 16:28:16,551 -  nornir.core -     INFO -        run() - Running task 'netmiko_send_command' with args {'command_string': 'show interface switchport', 'use_textfsm': True} on 2 hosts
2019-11-09 16:28:22,999 - nornir.core.task -    ERROR -      start() - Host 'NXOS-1': task 'netmiko_send_command' failed with traceback:
Traceback (most recent call last):
  File "/usr/local/lib/python3.7/site-packages/nornir/core/task.py", line 85, in start
    r = self.task(self, **self.params)
  File "/usr/local/lib/python3.7/site-packages/nornir/plugins/tasks/networking/netmiko_send_command.py", line 32, in netmiko_send_command
    result = net_connect.send_command(command_string, **kwargs)
  File "/usr/local/lib/python3.7/site-packages/netmiko/base_connection.py", line 1355, in send_command
    output, platform=self.device_type, command=command_string.strip()
  File "/usr/local/lib/python3.7/site-packages/netmiko/utilities.py", line 262, in get_structured_data
    template_dir = get_template_dir()
  File "/usr/local/lib/python3.7/site-packages/netmiko/utilities.py", line 245, in get_template_dir
    raise ValueError(msg)
ValueError: 
Valid ntc-templates not found, please install https://github.com/networktocode/ntc-templates
and then set the NET_TEXTFSM environment variable to point to the ./ntc-templates/templates
directory.

2019-11-09 16:28:23,227 - nornir.core.task -    ERROR -      start() - Host 'NXOS-2': task 'netmiko_send_command' failed with traceback:
Traceback (most recent call last):
  File "/usr/local/lib/python3.7/site-packages/nornir/core/task.py", line 85, in start
    r = self.task(self, **self.params)
  File "/usr/local/lib/python3.7/site-packages/nornir/plugins/tasks/networking/netmiko_send_command.py", line 32, in netmiko_send_command
    result = net_connect.send_command(command_string, **kwargs)
  File "/usr/local/lib/python3.7/site-packages/netmiko/base_connection.py", line 1355, in send_command
    output, platform=self.device_type, command=command_string.strip()
  File "/usr/local/lib/python3.7/site-packages/netmiko/utilities.py", line 262, in get_structured_data
    template_dir = get_template_dir()
  File "/usr/local/lib/python3.7/site-packages/netmiko/utilities.py", line 245, in get_template_dir
    raise ValueError(msg)
ValueError: 
Valid ntc-templates not found, please install https://github.com/networktocode/ntc-templates
and then set the NET_TEXTFSM environment variable to point to the ./ntc-templates/templates
directory.

2019-11-09 16:29:42,049 -  nornir.core -     INFO -        run() - Running task 'netmiko_send_command' with args {'command_string': 'show interface switchport', 'use_textfsm': True} on 2 hosts
2019-11-09 16:30:47,528 -  nornir.core -     INFO -        run() - Running task 'netmiko_send_command' with args {'command_string': 'show interface switchport', 'use_textfsm': True} on 2 hosts
2019-11-09 16:31:07,245 -  nornir.core -     INFO -        run() - Running task 'netmiko_send_command' with args {'command_string': 'show interface switchport', 'use_textfsm': True} on 2 hosts
2019-11-09 16:31:13,833 -  nornir.core -     INFO -        run() - Running task 'push_configs' with args {} on 2 hosts
2019-11-09 16:34:25,836 -  nornir.core -     INFO -        run() - Running task 'netmiko_send_command' with args {'command_string': 'show interface switchport', 'use_textfsm': True} on 2 hosts
2019-11-09 16:34:32,341 -  nornir.core -     INFO -        run() - Running task 'push_configs' with args {} on 2 hosts
